Workbook

Sheet Inputs
A1: CHILD CARE SUBSIDY (CCS) CALCULATOR — INPUTS
A2: Enter your family details below. Blue cells on yellow background are editable inputs. All other cells are formulas. See Cell Legend (columns K-N) for full details. | K2: CELL LEGEND
K3: Color | L3: Type | M3: Cells | N3: Editable?
A4: SECTION 1: FAMILY INCOME | K4: SAMPLE | L4: 🔵 USER INPUT | M4: Blue text, yellow fill | N4: ✅ YES
B5: Combined Family Income (annual) | C5: 120000 | D5: ← Enter your annual family income | K5: SAMPLE | L5: ⚫ FORMULA | M5: Black text, auto-calculated | N5: ❌ NO
B6: CCS Withholding Rate | C6: 0.05 | D6: ← Default 5% (0–100%) | K6: SAMPLE | L6: 🟢 LINKED FORMULA | M6: Green text, cross-tab link | N6: ❌ NO
B7: Number of Children in Care | C7: 2 | D7: ← 1 to 6 children | K7: SAMPLE | L7: 🔴 KEY OUTPUT | M7: Red text, final results | N7: ❌ NO
B8: 3-Day Guarantee Applies? | C8: Yes | D8: ← Yes/No (effective 5 Jan 2026) | K8: SAMPLE | L8: 🟡 HIGHLIGHT TOTAL | M8: Yellow fill, summary row | N8: ❌ NO
A10: SECTION 2: CHILD DETAILS | K10: CELL MAP — SECTION 1: FAMILY
B11: Child Details | C11: Child 1 | D11: Child 2 | E11: Child 3 | F11: Child 4 | G11: Child 5 | H11: Child 6 | K11: Cell | L11: Field | M11: Type | N11: Notes
B12: Child Name | C12: Emma | D12: Jack | K12: C5 | L12: Family Income | M12: 🔵 INPUT | N12: Annual combined income
B13: Age (years) | C13: 3 | D13: 7 | K13: C6 | L13: Withholding % | M13: 🔵 INPUT | N13: Default 5%, range 0–100%
B14: Care Type | C14: CBDC | D14: OSHC | K14: C7 | L14: # Children | M14: 🔵 INPUT | N14: 1 to 6 children
B15: School Age? (Yes/No) | C15: No | D15: Yes | K15: C8 | L15: 3-Day Guarantee | M15: 🔵 INPUT | N15: Yes/No (new from Jan 2026)
B16: Hourly Fee Charged ($) | C16: 13.5 | D16: 11
B17: Hours per Week | C17: 40 | D17: 15 | K17: CELL MAP — SECTION 2: PER-CHILD (×6)
B18: Days per Week | C18: 5 | D18: 5 | K18: Row | L18: Field | M18: Type | N18: Notes
B19: Weeks per Year in Care | C19: 48 | D19: 40 | K19: Row 12 | L19: Child Name | M19: 🔵 INPUT | N19: Leave blank if unused
B20: Higher CCS Eligible? | C20: =IF(C12="","","No") -> No | D20: =IF(D12="","",IF(AND(D13<=5,C$7>=2),"Yes","No")) -> No | E20: =IF(E12="","",IF(AND(E13<=5,C$7>=3),"Yes","No")) | F20: =IF(F12="","",IF(AND(F13<=5,C$7>=4),"Yes","No")) | G20: =IF(G12="","",IF(AND(G13<=5,C$7>=5),"Yes","No")) | H20: =IF(H12="","",IF(AND(H13<=5,C$7>=6),"Yes","No")) | K20: Row 13 | L20: Age (years) | M20: 🔵 INPUT | N20: Drives rate cap + Higher CCS
B21: Activity Test Hours/Fortnight | C21: 72 | D21: 72 | K21: Row 14 | L21: Care Type | M21: 🔵 INPUT | N21: Dropdown: CBDC/OSHC/FDC/IHC
B22: ACCS Type (if any) | C22: None | D22: None | K22: Row 15 | L22: School Age? | M22: ⚫ FORMULA | N22: Auto: Yes if age > 5
K23: Row 16 | L23: Hourly Fee ($) | M23: 🔵 INPUT | N23: Provider's hourly rate
B24: Care Types: CBDC = Centre Based Day Care | OSHC = Outside School Hours Care | FDC = Family Day Care | IHC = In Home Care | K24: Row 17 | L24: Hours/Week | M24: 🔵 INPUT | N24: Hours booked per week
K25: Row 18 | L25: Days/Week | M25: 🔵 INPUT | N25: Days per week in care
A26: SECTION 3: QUICK RESULTS SUMMARY | K26: Row 19 | L26: Weeks/Year | M26: 🔵 INPUT | N26: Weeks per year in care
B27: Results | C27: Child 1 | D27: Child 2 | E27: Child 3 | F27: Child 4 | G27: Child 5 | H27: Child 6 | J27: TOTAL | K27: Row 20 | L27: Higher CCS? | M27: ⚫ FORMULA | N27: Auto: 2nd+ child ≤5 yrs
B28: Your CCS % | C28: =IF(C12="","",IF(C20="Yes",VLOOKUP($C$5,'Rate Tables'!$A$5:$D$95,4,TRUE),VLOOKUP($C$5,'Rate Tables'!$A$5:$D$95,3,TRUE))) -> 0.83 | D28: =IF(D12="","",IF(D20="Yes",VLOOKUP($C$5,'Rate Tables'!$A$5:$D$95,4,TRUE),VLOOKUP($C$5,'Rate Tables'!$A$5:$D$95,3,TRUE))) -> 0.83 | E28: =IF(E12="","",IF(E20="Yes",VLOOKUP($C$5,'Rate Tables'!$A$5:$D$95,4,TRUE),VLOOKUP($C$5,'Rate Tables'!$A$5:$D$95,3,TRUE))) | F28: =IF(F12="","",IF(F20="Yes",VLOOKUP($C$5,'Rate Tables'!$A$5:$D$95,4,TRUE),VLOOKUP($C$5,'Rate Tables'!$A$5:$D$95,3,TRUE))) | G28: =IF(G12="","",IF(G20="Yes",VLOOKUP($C$5,'Rate Tables'!$A$5:$D$95,4,TRUE),VLOOKUP($C$5,'Rate Tables'!$A$5:$D$95,3,TRUE))) | H28: =IF(H12="","",IF(H20="Yes",VLOOKUP($C$5,'Rate Tables'!$A$5:$D$95,4,TRUE),VLOOKUP($C$5,'Rate Tables'!$A$5:$D$95,3,TRUE))) | K28: Row 21 | L28: Activity Hrs/Fn | M28: 🔵 INPUT | N28: Parent activity test hours
B29: Hourly Rate Cap | C29: =IF(C12="","",IF(C14="IHC",Assumptions!$B$18,IF(C15="Yes",IF(C14="CBDC",Assumptions!$C$15,IF(C14="OSHC",Assumptions!$C$16,IF(C14="FDC",Assumptions!$C$17,0))),IF(C14="CBDC",Assumptions!$B$15,IF(C14="OSHC",Assumptions!$B$16,IF(C14="FDC",Assumptions!$B$17,0)))))) -> 14.63 | D29: =IF(D12="","",IF(D14="IHC",Assumptions!$B$18,IF(D15="Yes",IF(D14="CBDC",Assumptions!$C$15,IF(D14="OSHC",Assumptions!$C$16,IF(D14="FDC",Assumptions!$C$17,0))),IF(D14="CBDC",Assumptions!$B$15,IF(D14="OSHC",Assumptions!$B$16,IF(D14="FDC",Assumptions!$B$17,0)))))) -> 12.81 | E29: =IF(E12="","",IF(E14="IHC",Assumptions!$B$18,IF(E15="Yes",IF(E14="CBDC",Assumptions!$C$15,IF(E14="OSHC",Assumptions!$C$16,IF(E14="FDC",Assumptions!$C$17,0))),IF(E14="CBDC",Assumptions!$B$15,IF(E14="OSHC",Assumptions!$B$16,IF(E14="FDC",Assumptions!$B$17,0)))))) | F29: =IF(F12="","",IF(F14="IHC",Assumptions!$B$18,IF(F15="Yes",IF(F14="CBDC",Assumptions!$C$15,IF(F14="OSHC",Assumptions!$C$16,IF(F14="FDC",Assumptions!$C$17,0))),IF(F14="CBDC",Assumptions!$B$15,IF(F14="OSHC",Assumptions!$B$16,IF(F14="FDC",Assumptions!$B$17,0)))))) | G29: =IF(G12="","",IF(G14="IHC",Assumptions!$B$18,IF(G15="Yes",IF(G14="CBDC",Assumptions!$C$15,IF(G14="OSHC",Assumptions!$C$16,IF(G14="FDC",Assumptions!$C$17,0))),IF(G14="CBDC",Assumptions!$B$15,IF(G14="OSHC",Assumptions!$B$16,IF(G14="FDC",Assumptions!$B$17,0)))))) | H29: =IF(H12="","",IF(H14="IHC",Assumptions!$B$18,IF(H15="Yes",IF(H14="CBDC",Assumptions!$C$15,IF(H14="OSHC",Assumptions!$C$16,IF(H14="FDC",Assumptions!$C$17,0))),IF(H14="CBDC",Assumptions!$B$15,IF(H14="OSHC",Assumptions!$B$16,IF(H14="FDC",Assumptions!$B$17,0)))))) | K29: Row 22 | L29: ACCS Type | M29: 🔵 INPUT | N29: None / Transition to Work
B30: CCS per Hour | C30: =IF(C12="","",MIN(C16,C29)*C28) -> 11.205 | D30: =IF(D12="","",MIN(D16,D29)*D28) -> 9.13 | E30: =IF(E12="","",MIN(E16,E29)*E28) | F30: =IF(F12="","",MIN(F16,F29)*F28) | G30: =IF(G12="","",MIN(G16,G29)*G28) | H30: =IF(H12="","",MIN(H16,H29)*H28)
B31: Gap Fee per Hour | C31: =IF(C12="","",C16-C30) -> 2.295 | D31: =IF(D12="","",D16-D30) -> 1.87 | E31: =IF(E12="","",E16-E30) | F31: =IF(F12="","",F16-F30) | G31: =IF(G12="","",G16-G30) | H31: =IF(H12="","",H16-H30) | K31: CELL MAP - SECTION 3: RESULTS
B32: Weekly Cost (before CCS) | C32: =IF(C12="","",C16*C17) -> 540 | D32: =IF(D12="","",D16*D17) -> 165 | E32: =IF(E12="","",E16*E17) | F32: =IF(F12="","",F16*F17) | G32: =IF(G12="","",G16*G17) | H32: =IF(H12="","",H16*H17) | J32: =SUM(C32:H32) -> 705 | K32: Row | L32: Field | M32: Type | N32: Notes
B33: Weekly CCS Received | C33: =IF(C12="","",C30*C17*(1-$C$6)) -> 425.79 | D33: =IF(D12="","",D30*D17*(1-$C$6)) -> 130.1025 | E33: =IF(E12="","",E30*E17*(1-$C$6)) | F33: =IF(F12="","",F30*F17*(1-$C$6)) | G33: =IF(G12="","",G30*G17*(1-$C$6)) | H33: =IF(H12="","",H30*H17*(1-$C$6)) | J33: =SUM(C33:H33) -> 555.8925 | K33: Row 28 | L33: CCS % | M33: FORMULA | N33: VLOOKUP to Rate Tables
B34: Weekly Out-of-Pocket | C34: =IF(C12="","",C32-C33) -> 114.21 | D34: =IF(D12="","",D32-D33) -> 34.8975 | E34: =IF(E12="","",E32-E33) | F34: =IF(F12="","",F32-F33) | G34: =IF(G12="","",G32-G33) | H34: =IF(H12="","",H32-H33) | J34: =SUM(C34:H34) -> 149.1075 | K34: Row 29 | L34: Hourly Rate Cap | M34: FORMULA | N34: Links to Assumptions tab
B35: Annual Out-of-Pocket | C35: =IF(C12="","",C34*C19) -> 5482.08 | D35: =IF(D12="","",D34*D19) -> 1395.9 | E35: =IF(E12="","",E34*E19) | F35: =IF(F12="","",F34*F19) | G35: =IF(G12="","",G34*G19) | H35: =IF(H12="","",H34*H19) | J35: =SUM(C35:H35) -> 6877.98 | K35: Row 30 | L35: CCS per Hour | M35: FORMULA | N35: MIN(fee,cap) x CCS%
K36: Row 31 | L36: Gap Fee/Hr | M36: FORMULA | N36: Fee - CCS per hour
A37: SECTION 4: FAMILY TOTALS SUMMARY | K37: Row 32 | L37: Weekly Cost | M37: FORMULA | N37: Fee x Hours per week
B38: Period | C38: Total Childcare Cost | D38: CCS Received | E38: Out-of-Pocket Cost | F38: CCS as % of Fees | K38: Row 33 | L38: Weekly CCS | M38: LINKED | N38: Net of withholding rate
B39: Weekly | C39: =J32 -> 705 | D39: =J33 -> 555.8925 | E39: =J34 -> 149.1075 | F39: =IF(C39=0,"-",D39/C39) -> 0.7885 | K39: Row 34 | L39: Weekly OOP | M39: OUTPUT | N39: Cost minus CCS received
B40: Fortnightly | C40: =C39*2 -> 1410 | D40: =D39*2 -> 1111.785 | E40: =E39*2 -> 298.215 | F40: =F39 -> 0.7885 | K40: Row 35 | L40: Annual OOP | M40: OUTPUT | N40: Weekly OOP x Weeks/yr
B41: Annual | C41: =J32*Assumptions!B53 -> 36660 | D41: =J33*Assumptions!B53 -> 28906.41 | E41: =C41-D41 -> 7753.59 | F41: =F39 -> 0.7885

Sheet Dashboard
A1: CCS CALCULATOR — DASHBOARD
A2: Automated summary — all data flows from the Inputs tab
A3: ⬅ Back to Inputs
A4: KEY METRICS
B5: Family Income | C5: =Inputs!C5 -> 120000 | D5: Children in Care | E5: =Inputs!C7 -> 2 | F5: Standard CCS % | G5: =Calculations!C17 -> 0.83
B7: Annual Gross Fees | C7: =Calculations!C46 -> 36660 | D7: Annual CCS Received | E7: =Calculations!F46 -> 28906.41 | F7: Annual Out-of-Pocket | G7: =Calculations!G46 -> 7753.59
A10: PER-CHILD WEEKLY BREAKDOWN
B11: Child | C11: Weekly CCS Paid | D11: Weekly Out-of-Pocket
B12: =IF(Calculations!C$15="No","",Inputs!C12) -> Emma | C12: =IF(Calculations!C$15="No","",Calculations!C39) -> 425.79 | D12: =IF(Calculations!C$15="No","",Calculations!C40) -> 114.21
B13: =IF(Calculations!D$15="No","",Inputs!D12) -> Jack | C13: =IF(Calculations!D$15="No","",Calculations!D39) -> 130.1025 | D13: =IF(Calculations!D$15="No","",Calculations!D40) -> 34.8975
B14: =IF(Calculations!E$15="No","",Inputs!E12) | C14: =IF(Calculations!E$15="No","",Calculations!E39) | D14: =IF(Calculations!E$15="No","",Calculations!E40)
B15: =IF(Calculations!F$15="No","",Inputs!F12) | C15: =IF(Calculations!F$15="No","",Calculations!F39) | D15: =IF(Calculations!F$15="No","",Calculations!F40)
B16: =IF(Calculations!G$15="No","",Inputs!G12) | C16: =IF(Calculations!G$15="No","",Calculations!G39) | D16: =IF(Calculations!G$15="No","",Calculations!G40)
B17: =IF(Calculations!H$15="No","",Inputs!H12) | C17: =IF(Calculations!H$15="No","",Calculations!H39) | D17: =IF(Calculations!H$15="No","",Calculations!H40)
A19: ANNUAL COST BREAKDOWN
B20: Component | C20: Annual Amount
B21: CCS Paid to You | C21: =Calculations!F46 -> 28906.41
B22: Withholding (returned at EOFY) | C22: =Calculations!E46 -> 1521.39
B23: Your Out-of-Pocket | C23: =Calculations!G46 -> 7753.59
A25: INCOME SENSITIVITY CURVE DATA
B26: Family Income | C26: CCS % | D26: Annual Out-of-Pocket | E26: Family Income | F26: Annual Out-of-Pocket
B27: 50000 | C27: =VLOOKUP(B27,'Rate Tables'!$A$5:$D$95,3,TRUE) -> 0.9 | D27: =Calculations!$C$46*(1-C27*(1-Inputs!$C$6)) -> 5315.7 | E27: =B27 -> 50000 | F27: =D27 -> 5315.7
B28: 75000 | C28: =VLOOKUP(B28,'Rate Tables'!$A$5:$D$95,3,TRUE) -> 0.9 | D28: =Calculations!$C$46*(1-C28*(1-Inputs!$C$6)) -> 5315.7 | E28: =B28 -> 75000 | F28: =D28 -> 5315.7
B29: 100000 | C29: =VLOOKUP(B29,'Rate Tables'!$A$5:$D$95,3,TRUE) -> 0.87 | D29: =Calculations!$C$46*(1-C29*(1-Inputs!$C$6)) -> 6360.51 | E29: =B29 -> 100000 | F29: =D29 -> 6360.51
B30: 120000 | C30: =VLOOKUP(B30,'Rate Tables'!$A$5:$D$95,3,TRUE) -> 0.83 | D30: =Calculations!$C$46*(1-C30*(1-Inputs!$C$6)) -> 7753.59 | E30: =B30 -> 120000 | F30: =D30 -> 7753.59
B31: 150000 | C31: =VLOOKUP(B31,'Rate Tables'!$A$5:$D$95,3,TRUE) -> 0.77 | D31: =Calculations!$C$46*(1-C31*(1-Inputs!$C$6)) -> 9843.21 | E31: =B31 -> 150000 | F31: =D31 -> 9843.21
B32: 175000 | C32: =VLOOKUP(B32,'Rate Tables'!$A$5:$D$95,3,TRUE) -> 0.72 | D32: =Calculations!$C$46*(1-C32*(1-Inputs!$C$6)) -> 11584.56 | E32: =B32 -> 175000 | F32: =D32 -> 11584.56
B33: 200000 | C33: =VLOOKUP(B33,'Rate Tables'!$A$5:$D$95,3,TRUE) -> 0.67 | D33: =Calculations!$C$46*(1-C33*(1-Inputs!$C$6)) -> 13325.91 | E33: =B33 -> 200000 | F33: =D33 -> 13325.91
B34: 225000 | C34: =VLOOKUP(B34,'Rate Tables'!$A$5:$D$95,3,TRUE) -> 0.62 | D34: =Calculations!$C$46*(1-C34*(1-Inputs!$C$6)) -> 15067.26 | E34: =B34 -> 225000 | F34: =D34 -> 15067.26
B35: 250000 | C35: =VLOOKUP(B35,'Rate Tables'!$A$5:$D$95,3,TRUE) -> 0.57 | D35: =Calculations!$C$46*(1-C35*(1-Inputs!$C$6)) -> 16808.61 | E35: =B35 -> 250000 | F35: =D35 -> 16808.61
B36: 275000 | C36: =VLOOKUP(B36,'Rate Tables'!$A$5:$D$95,3,TRUE) -> 0.52 | D36: =Calculations!$C$46*(1-C36*(1-Inputs!$C$6)) -> 18549.96 | E36: =B36 -> 275000 | F36: =D36 -> 18549.96
B37: 300000 | C37: =VLOOKUP(B37,'Rate Tables'!$A$5:$D$95,3,TRUE) -> 0.47 | D37: =Calculations!$C$46*(1-C37*(1-Inputs!$C$6)) -> 20291.31 | E37: =B37 -> 300000 | F37: =D37 -> 20291.31
B38: 325000 | C38: =VLOOKUP(B38,'Rate Tables'!$A$5:$D$95,3,TRUE) -> 0.42 | D38: =Calculations!$C$46*(1-C38*(1-Inputs!$C$6)) -> 22032.66 | E38: =B38 -> 325000 | F38: =D38 -> 22032.66
... B47: 550000 | C47: =VLOOKUP(B47,'Rate Tables'!$A$5:$D$95,3,TRUE) -> 0 | D47: =Calculations!$C$46*(1-C47*(1-Inputs!$C$6)) -> 36660 | E47: =B47 -> 550000 | F47: =D47 -> 36660

Sheet Calculations
A1: CHILD CARE SUBSIDY (CCS) — DETAILED CALCULATIONS
A2: All calculations reference the Inputs tab. Do not edit this sheet directly.
A3: ⬅ Back to Inputs
A4: STEP 1: INPUT SUMMARY (from Inputs tab)
C5: Child 1 | D5: Child 2 | E5: Child 3 | F5: Child 4 | G5: Child 5 | H5: Child 6 | I5: TOTAL
B6: Family Income | C6: =Inputs!C5 -> 120000 | D6: =Inputs!C5 -> 120000 | E6: =Inputs!C5 -> 120000 | F6: =Inputs!C5 -> 120000 | G6: =Inputs!C5 -> 120000 | H6: =Inputs!C5 -> 120000
B7: Child Name | C7: =Inputs!C12 -> Emma | D7: =Inputs!D12 -> Jack | E7: =Inputs!E12 -> 0 | F7: =Inputs!F12 -> 0 | G7: =Inputs!G12 -> 0 | H7: =Inputs!H12 -> 0
B8: Age | C8: =Inputs!C13 -> 3 | D8: =Inputs!D13 -> 7 | E8: =Inputs!E13 -> 0 | F8: =Inputs!F13 -> 0 | G8: =Inputs!G13 -> 0 | H8: =Inputs!H13 -> 0
B9: Care Type | C9: =Inputs!C14 -> CBDC | D9: =Inputs!D14 -> OSHC | E9: =Inputs!E14 -> 0 | F9: =Inputs!F14 -> 0 | G9: =Inputs!G14 -> 0 | H9: =Inputs!H14 -> 0
B10: School Age | C10: =Inputs!C15 -> No | D10: =Inputs!D15 -> Yes | E10: =Inputs!E15 -> 0 | F10: =Inputs!F15 -> 0 | G10: =Inputs!G15 -> 0 | H10: =Inputs!H15 -> 0
B11: Hourly Fee Charged | C11: =Inputs!C16 -> 13.5 | D11: =Inputs!D16 -> 11 | E11: =Inputs!E16 -> 0 | F11: =Inputs!F16 -> 0 | G11: =Inputs!G16 -> 0 | H11: =Inputs!H16 -> 0
B12: Hours per Week | C12: =Inputs!C17 -> 40 | D12: =Inputs!D17 -> 15 | E12: =Inputs!E17 -> 0 | F12: =Inputs!F17 -> 0 | G12: =Inputs!G17 -> 0 | H12: =Inputs!H17 -> 0
B13: Weeks per Year | C13: =Inputs!C19 -> 48 | D13: =Inputs!D19 -> 40 | E13: =Inputs!E19 -> 0 | F13: =Inputs!F19 -> 0 | G13: =Inputs!G19 -> 0 | H13: =Inputs!H19 -> 0
B14: Higher CCS Eligible | C14: =Inputs!C20 -> No | D14: =Inputs!D20 -> No | E14: =Inputs!E20 | F14: =Inputs!F20 | G14: =Inputs!G20 | H14: =Inputs!H20
B15: Active (based on # children) | C15: =IF(1<=Inputs!$C$7,"Yes","No") -> Yes | D15: =IF(2<=Inputs!$C$7,"Yes","No") -> Yes | E15: =IF(3<=Inputs!$C$7,"Yes","No") -> No | F15: =IF(4<=Inputs!$C$7,"Yes","No") -> No | G15: =IF(5<=Inputs!$C$7,"Yes","No") -> No | H15: =IF(6<=Inputs!$C$7,"Yes","No") -> No
A16: STEP 2: CCS PERCENTAGE DETERMINATION
B17: Standard CCS % (from Rate Table) | C17: =IF(C$15="No","",VLOOKUP(C6,'Rate Tables'!$A$5:$D$95,3,TRUE)) -> 0.83 | D17: =IF(D$15="No","",VLOOKUP(D6,'Rate Tables'!$A$5:$D$95,3,TRUE)) -> 0.83 | E17: =IF(E$15="No","",VLOOKUP(E6,'Rate Tables'!$A$5:$D$95,3,TRUE)) | F17: =IF(F$15="No","",VLOOKUP(F6,'Rate Tables'!$A$5:$D$95,3,TRUE)) | G17: =IF(G$15="No","",VLOOKUP(G6,'Rate Tables'!$A$5:$D$95,3,TRUE)) | H17: =IF(H$15="No","",VLOOKUP(H6,'Rate Tables'!$A$5:$D$95,3,TRUE))
B18: Higher CCS % (if eligible) | C18: =IF(C$15="No","",VLOOKUP(C6,'Rate Tables'!$A$5:$D$95,4,TRUE)) -> 0.95 | D18: =IF(D$15="No","",VLOOKUP(D6,'Rate Tables'!$A$5:$D$95,4,TRUE)) -> 0.95 | E18: =IF(E$15="No","",VLOOKUP(E6,'Rate Tables'!$A$5:$D$95,4,TRUE)) | F18: =IF(F$15="No","",VLOOKUP(F6,'Rate Tables'!$A$5:$D$95,4,TRUE)) | G18: =IF(G$15="No","",VLOOKUP(G6,'Rate Tables'!$A$5:$D$95,4,TRUE)) | H18: =IF(H$15="No","",VLOOKUP(H6,'Rate Tables'!$A$5:$D$95,4,TRUE))
B19: Higher CCS Eligible? | C19: =C14 -> No | D19: =D14 -> No | E19: =E14 | F19: =F14 | G19: =G14 | H19: =H14
B20: APPLICABLE CCS % | C20: =IF(C$15="No","",IF(C19="Yes",C18,C17)) -> 0.83 | D20: =IF(D$15="No","",IF(D19="Yes",D18,D17)) -> 0.83 | E20: =IF(E$15="No","",IF(E19="Yes",E18,E17)) | F20: =IF(F$15="No","",IF(F19="Yes",F18,F17)) | G20: =IF(G$15="No","",IF(G19="Yes",G18,G17)) | H20: =IF(H$15="No","",IF(H19="Yes",H18,H17))
B21: ACCS Override % (if applicable) | C21: =IF(C$15="No","",IF(Inputs!C22="Transition to Work",Assumptions!B48,IF(OR(Inputs!C22="Grandparent",Inputs!C22="Hardship",Inputs!C22="Wellbeing"),Assumptions!B49,"-"))) -> - | D21: =IF(D$15="No","",IF(Inputs!D22="Transition to Work",Assumptions!C48,IF(OR(Inputs!D22="Grandparent",Inputs!D22="Hardship",Inputs!D22="Wellbeing"),Assumptions!C49,"-"))) -> - | E21: =IF(E$15="No","",IF(Inputs!E22="Transition to Work",Assumptions!D48,IF(OR(Inputs!E22="Grandparent",Inputs!E22="Hardship",Inputs!E22="Wellbeing"),Assumptions!D49,"-"))) | F21: =IF(F$15="No","",IF(Inputs!F22="Transition to Work",Assumptions!E48,IF(OR(Inputs!F22="Grandparent",Inputs!F22="Hardship",Inputs!F22="Wellbeing"),Assumptions!E49,"-"))) | G21: =IF(G$15="No","",IF(Inputs!G22="Transition to Work",Assumptions!F48,IF(OR(Inputs!G22="Grandparent",Inputs!G22="Hardship",Inputs!G22="Wellbeing"),Assumptions!F49,"-"))) | H21: =IF(H$15="No","",IF(Inputs!H22="Transition to Work",Assumptions!G48,IF(OR(Inputs!H22="Grandparent",Inputs!H22="Hardship",Inputs!H22="Wellbeing"),Assumptions!G49,"-")))
A23: STEP 3: HOURLY RATE CAP & SUBSIDISED HOURS
B24: Hourly Rate Cap (from Assumptions) | C24: =IF(C$15="No","",Inputs!C29) -> 14.63 | D24: =IF(D$15="No","",Inputs!D29) -> 12.81 | E24: =IF(E$15="No","",Inputs!E29) | F24: =IF(F$15="No","",Inputs!F29) | G24: =IF(G$15="No","",Inputs!G29) | H24: =IF(H$15="No","",Inputs!H29)
B25: Hourly Fee Charged | C25: =IF(C$15="No","",C11) -> 13.5 | D25: =IF(D$15="No","",D11) -> 11 | E25: =IF(E$15="No","",E11) | F25: =IF(F$15="No","",F11) | G25: =IF(G$15="No","",G11) | H25: =IF(H$15="No","",H11)
B26: ASSESSABLE HOURLY RATE (lower of fee/cap) | C26: =IF(C$15="No","",MIN(C24,C25)) -> 13.5 | D26: =IF(D$15="No","",MIN(D24,D25)) -> 11 | E26: =IF(E$15="No","",MIN(E24,E25)) | F26: =IF(F$15="No","",MIN(F24,F25)) | G26: =IF(G$15="No","",MIN(G24,G25)) | H26: =IF(H$15="No","",MIN(H24,H25))
B27: Activity Test Hours/Fortnight | C27: =IF(C$15="No","",Inputs!C21) -> 72 | D27: =IF(D$15="No","",Inputs!D21) -> 72 | E27: =IF(E$15="No","",Inputs!E21) | F27: =IF(F$15="No","",Inputs!F21) | G27: =IF(G$15="No","",Inputs!G21) | H27: =IF(H$15="No","",Inputs!H21)
B28: 3-Day Guarantee Hours/Fortnight | C28: =IF(C$15="No","",IF(Inputs!C$8="Yes",IF(C27>=48,Assumptions!B26,Assumptions!B25),C27)) -> 100 | D28: =IF(D$15="No","",IF(Inputs!D$8="Yes",IF(D27>=48,Assumptions!C26,Assumptions!C25),D27)) -> 72 | E28: =IF(E$15="No","",IF(Inputs!E$8="Yes",IF(E27>=48,Assumptions!D26,Assumptions!D25),E27)) | F28: =IF(F$15="No","",IF(Inputs!F$8="Yes",IF(F27>=48,Assumptions!E26,Assumptions!E25),F27)) | G28: =IF(G$15="No","",IF(Inputs!G$8="Yes",IF(G27>=48,Assumptions!F26,Assumptions!F25),G27)) | H28: =IF(H$15="No","",IF(Inputs!H$8="Yes",IF(H27>=48,Assumptions!G26,Assumptions!G25),H27))
B29: SUBSIDISED HOURS/FORTNIGHT | C29: =IF(C$15="No","",MAX(C27,C28)) -> 100 | D29: =IF(D$15="No","",MAX(D27,D28)) -> 72 | E29: =IF(E$15="No","",MAX(E27,E28)) | F29: =IF(F$15="No","",MAX(F27,F28)) | G29: =IF(G$15="No","",MAX(G27,G28)) | H29: =IF(H$15="No","",MAX(H27,H28))
B30: Subsidised Hours/Week | C30: =IF(C$15="No","",C29/2) -> 50 | D30: =IF(D$15="No","",D29/2) -> 36 | E30: =IF(E$15="No","",E29/2) | F30: =IF(F$15="No","",F29/2) | G30: =IF(G$15="No","",G29/2) | H30: =IF(H$15="No","",H29/2)
A32: STEP 4: SUBSIDY CALCULATION
B33: CCS per Hour = Assessable Rate × CCS % | C33: =IF(C$15="No","",C26*C20) -> 11.205 | D33: =IF(D$15="No","",D26*D20) -> 9.13 | E33: =IF(E$15="No","",E26*E20) | F33: =IF(F$15="No","",F26*F20) | G33: =IF(G$15="No","",G26*G20) | H33: =IF(H$15="No","",H26*H20)
B34: Hours Actually Used per Week | C34: =IF(C$15="No","",MIN(C12,C30)) -> 40 | D34: =IF(D$15="No","",MIN(D12,D30)) -> 15 | E34: =IF(E$15="No","",MIN(E12,E30)) | F34: =IF(F$15="No","",MIN(F12,F30)) | G34: =IF(G$15="No","",MIN(G12,G30)) | H34: =IF(H$15="No","",MIN(H12,H30))
B35: Weekly Gross Fee (hourly fee × hrs) | C35: =IF(C$15="No","",C11*C34) -> 540 | D35: =IF(D$15="No","",D11*D34) -> 165 | E35: =IF(E$15="No","",E11*E34) | F35: =IF(F$15="No","",F11*F34) | G35: =IF(G$15="No","",G11*G34) | H35: =IF(H$15="No","",H11*H34) | I35: =SUM(C35:H35) -> 705
B36: Weekly CCS (before withholding) | C36: =IF(C$15="No","",C33*C34) -> 448.2 | D36: =IF(D$15="No","",D33*D34) -> 136.95 | E36: =IF(E$15="No","",E33*E34) | F36: =IF(F$15="No","",F33*F34) | G36: =IF(G$15="No","",G33*G34) | H36: =IF(H$15="No","",H33*H34) | I36: =SUM(C36:H36) -> 585.15
B37: Withholding Rate | C37: =IF(C$15="No","",Inputs!$C$6) -> 0.05 | D37: =IF(D$15="No","",Inputs!$C$6) -> 0.05 | E37: =IF(E$15="No","",Inputs!$C$6) | F37: =IF(F$15="No","",Inputs!$C$6) | G37: =IF(G$15="No","",Inputs!$C$6) | H37: =IF(H$15="No","",Inputs!$C$6)
B38: Weekly Withholding Amount | C38: =IF(C$15="No","",C36*C37) -> 22.41 | D38: =IF(D$15="No","",D36*D37) -> 6.8475 | E38: =IF(E$15="No","",E36*E37) | F38: =IF(F$15="No","",F36*F37) | G38: =IF(G$15="No","",G36*G37) | H38: =IF(H$15="No","",H36*H37) | I38: =SUM(C38:H38) -> 29.2575
B39: WEEKLY CCS PAID (after withholding) | C39: =IF(C$15="No","",C36-C38) -> 425.79 | D39: =IF(D$15="No","",D36-D38) -> 130.1025 | E39: =IF(E$15="No","",E36-E38) | F39: =IF(F$15="No","",F36-F38) | G39: =IF(G$15="No","",G36-G38) | H39: =IF(H$15="No","",H36-H38) | I39: =SUM(C39:H39) -> 555.8925
B40: WEEKLY OUT-OF-POCKET | C40: =IF(C$15="No","",C35-C39) -> 114.21 | D40: =IF(D$15="No","",D35-D39) -> 34.8975 | E40: =IF(E$15="No","",E35-E39) | F40: =IF(F$15="No","",F35-F39) | G40: =IF(G$15="No","",G35-G39) | H40: =IF(H$15="No","",H35-H39) | I40: =SUM(C40:H40) -> 149.1075
A42: STEP 5: PERIOD SUMMARIES
C43: Gross Fee | D43: CCS (gross) | E43: Withholding | F43: CCS Paid | G43: Out-of-Pocket | H43: Effective Rate
...

Sheet Assumptions
A1: CCS ASSUMPTIONS & PARAMETERS
A2: Financial Year 2025-26 (FY2026) — Effective from 7 July 2025
A3: ⬅ Back to Inputs
A4: SECTION 1: INCOME THRESHOLDS
A5: Parameter | B5: Value | C5: Unit | D5: Notes | E5: Source | F5: Reference URL
A6: Maximum CCS rate (lowest income) | B6: 0.9 | C6: % | D6: Families earning ≤$85,279 | E6: Dept of Education | F6: education.gov.au/early-childhood/providers/child-care-subsidy
A7: Lower income threshold | B7: 85279 | C7: $ | D7: CCS = 90% at or below this level | E7: Services Australia | F7: servicesaustralia.gov.au/child-care-subsidy
A8: Upper income threshold (0% CCS) | B8: 535279 | C8: $ | D8: CCS = 0% at or above this level | E8: Dept of Education | F8: education.gov.au/early-childhood/providers/child-care-subsidy
A9: CCS taper rate | B9: 0.01 | C9: per $5,000 | D9: CCS decreases 1% for every $5,000 above lower threshold | E9: Dept of Education | F9: education.gov.au/early-childhood/providers/child-care-subsidy
A10: Taper income step | B10: 5000 | C10: $ | D10: Income increment for each 1% reduction | E10: Dept of Education | F10: education.gov.au/early-childhood/providers/child-care-subsidy
A11: Higher CCS income cap (siblings) | B11: 367563 | C11: $ | D11: Higher rate ceases when family income ≥ this amount | E11: Dept of Education | F11: education.gov.au/early-childhood/providers/child-care-subsidy
A13: SECTION 2: HOURLY RATE CAPS BY CARE TYPE
A14: Care Type | B14: Below School Age | C14: School Age | D14: Notes | E14: Source | F14: Reference URL
A15: Centre Based Day Care (CBDC) | B15: 14.63 | C15: 12.81 | D15: Long Day Care & Occasional Care | E15: Dept of Education | F15: education.gov.au/early-childhood/announcements/child-care-subsidy-hourly-rate-caps-are-changing-soon-0
A16: Outside School Hours Care (OSHC) | B16: 14.63 | C16: 12.81 | D16: Before/After school, Vacation care | E16: Dept of Education | F16: education.gov.au/early-childhood/announcements/child-care-subsidy-hourly-rate-caps-are-changing-soon-0
A17: Family Day Care (FDC) | B17: 13.56 | C17: 13.56 | D17: Same rate for all ages | E17: familydaycare.com.au | F17: familydaycare.com.au/fdcm/11-june-2025
A18: In Home Care (IHC) | B18: 39.8 | C18: 39.8 | D18: Per FAMILY (not per child) | E18: Dept of Education | F18: blog.owna.com.au/post/new-ccs-rates-2025-26
A20: Note: | B20: CCS applies to the LOWER of the hourly fee charged OR the hourly rate cap.
A21: Effective: | B21: From 7 July 2025 (first CCS fortnight of FY2025-26). Adjusted annually by CPI.
A23: SECTION 3: ACTIVITY TEST & SUBSIDISED HOURS (3 Day Guarantee — from 5 Jan 2026)
A24: Activity Level / Circumstance | B24: Hours per Fortnight | C24: Hours per Week | D24: Notes | E24: Source | F24: Reference URL
A25: 3 Day Guarantee (all CCS eligible families) | B25: 72 | C25: 36 | D25: Minimum for ALL CCS families from 5 Jan 2026 | E25: Dept of Education | F25: education.gov.au/early-childhood/providers/child-care-subsidy
A26: Recognised activity > 48 hrs/fortnight | B26: 100 | C26: 50 | D26: Both parents must meet threshold (lower used) | E26: Services Australia | F26: servicesaustralia.gov.au/activity-level-and-subsidised-hours-for-child-care-subsidy
A27: First Nations child | B27: 100 | C27: 50 | D27: Guaranteed 100 hrs regardless of activity | E27: Dept of Education | F27: education.gov.au/early-childhood/providers/child-care-subsidy
A28: ACCS recipients | B28: 100 | C28: 50 | D28: Child Wellbeing, Temp Hardship, Grandparent | E28: Services Australia | F28: servicesaustralia.gov.au/child-care-subsidy
A29: CCS exemption holders | B29: 100 | C29: 50 | D29: Disability, exceptional circumstances | E29: Services Australia | F29: servicesaustralia.gov.au/child-care-subsidy
A30: Low income (≤$85,279) + no activity (pre-3DG) | B30: 24 | C30: 12 | D30: Safety net (superseded by 3DG for most) | E30: childcaresubsidy.com.au | F30: childcaresubsidy.com.au
A31: Preschool child + no activity (pre-3DG) | B31: 36 | C31: 18 | D31: Year before school, at CBDC service | E31: childcaresubsidy.com.au | F31: childcaresubsidy.com.au
A33: SECTION 4: HIGHER CCS FOR MULTIPLE CHILDREN
A34: Parameter | B34: Value | C34: Unit | D34: Notes | E34: Source | F34: Reference URL
A35: Standard rate child | B35: Eldest CCS-eligible child ≤5 | D35: Gets standard CCS rates based on income | E35: Dept of Education | F35: education.gov.au/early-childhood/providers/child-care-subsidy
A36: Higher rate child | B36: 2nd & younger children ≤5 | D36: Gets higher CCS rate (up to +30%) | E36: Dept of Education | F36: education.gov.au/early-childhood/providers/child-care-subsidy
A37: Maximum higher CCS boost | B37: 0.3 | C37: % | D37: Higher rate = Standard rate + up to 30% | E37: Dept of Education | F37: education.gov.au/early-childhood/providers/child-care-subsidy
A38: Higher CCS income cap | B38: 367563 | C38: $ | D38: Higher rate ceases at this income (FY26) | E38: Dept of Education | F38: education.gov.au/early-childhood/providers/child-care-subsidy
A39: IHC excluded from Higher CCS | B39: Yes | D39: In Home Care subsidised per family, not per child | E39: Dept of Education | F39: education.gov.au/early-childhood/providers/child-care-subsidy
A41: HIGHER CCS FORMULA: | B41: Higher rate child CCS% = MIN(Standard CCS% + 30%, 95%) | D41: Capped at 95% maximum; only if family income < $367,563
A42: SIBLINGS: | B42: Siblings do NOT need to attend the same service.
A44: SECTION 5: WITHHOLDING & ACCS
A45: Parameter | B45: Value | C45: Unit | D45: Notes | E45: Source | F45: Reference URL
A46: Default withholding rate | B46: 0.05 | C46: % | D46: 5% withheld until end-of-year reconciliation | E46: Services Australia | F46: servicesaustralia.gov.au/child-care-subsidy
...

Sheet Rate Tables
A1: CCS RATE LOOKUP TABLES — FY2025-26
A3: STANDARD CCS RATE TABLE
A4: Family Income From | B4: Family Income To | C4: Standard CCS % | D4: Higher CCS % (2nd+ Child ≤5)
A5: 0 | B5: =Assumptions!B7 -> 85279 | C5: 0.9 | D5: =IF(A5<Assumptions!$B$38, MIN(C5+Assumptions!$B$37, 0.95), C5) -> 0.95
A6: =Assumptions!B7+1 -> 85280 | B6: =A6+Assumptions!B10-1 -> 90279 | C6: =MAX(Assumptions!B6-((ROW()-5)*Assumptions!B9),0) -> 0.89 | D6: =IF(A6<Assumptions!$B$38, MIN(C6+Assumptions!$B$37, 0.95), C6) -> 0.95
A7: =A6+Assumptions!$B$10 -> 90280 | B7: =A7+Assumptions!$B$10-1 -> 95279 | C7: =MAX(Assumptions!$B$6-((ROW()-5)*Assumptions!$B$9),0) -> 0.88 | D7: =IF(A7<Assumptions!$B$38, MIN(C7+Assumptions!$B$37, 0.95), C7) -> 0.95
A8: =A7+Assumptions!$B$10 -> 95280 | B8: =A8+Assumptions!$B$10-1 -> 100279 | C8: =MAX(Assumptions!$B$6-((ROW()-5)*Assumptions!$B$9),0) -> 0.87 | D8: =IF(A8<Assumptions!$B$38, MIN(C8+Assumptions!$B$37, 0.95), C8) -> 0.95
A9: =A8+Assumptions!$B$10 -> 100280 | B9: =A9+Assumptions!$B$10-1 -> 105279 | C9: =MAX(Assumptions!$B$6-((ROW()-5)*Assumptions!$B$9),0) -> 0.86 | D9: =IF(A9<Assumptions!$B$38, MIN(C9+Assumptions!$B$37, 0.95), C9) -> 0.95
A10: =A9+Assumptions!$B$10 -> 105280 | B10: =A10+Assumptions!$B$10-1 -> 110279 | C10: =MAX(Assumptions!$B$6-((ROW()-5)*Assumptions!$B$9),0) -> 0.85 | D10: =IF(A10<Assumptions!$B$38, MIN(C10+Assumptions!$B$37, 0.95), C10) -> 0.95
A11: =A10+Assumptions!$B$10 -> 110280 | B11: =A11+Assumptions!$B$10-1 -> 115279 | C11: =MAX(Assumptions!$B$6-((ROW()-5)*Assumptions!$B$9),0) -> 0.84 | D11: =IF(A11<Assumptions!$B$38, MIN(C11+Assumptions!$B$37, 0.95), C11) -> 0.95
A12: =A11+Assumptions!$B$10 -> 115280 | B12: =A12+Assumptions!$B$10-1 -> 120279 | C12: =MAX(Assumptions!$B$6-((ROW()-5)*Assumptions!$B$9),0) -> 0.83 | D12: =IF(A12<Assumptions!$B$38, MIN(C12+Assumptions!$B$37, 0.95), C12) -> 0.95
A13: =A12+Assumptions!$B$10 -> 120280 | B13: =A13+Assumptions!$B$10-1 -> 125279 | C13: =MAX(Assumptions!$B$6-((ROW()-5)*Assumptions!$B$9),0) -> 0.82 | D13: =IF(A13<Assumptions!$B$38, MIN(C13+Assumptions!$B$37, 0.95), C13) -> 0.95
A14: =A13+Assumptions!$B$10 -> 125280 | B14: =A14+Assumptions!$B$10-1 -> 130279 | C14: =MAX(Assumptions!$B$6-((ROW()-5)*Assumptions!$B$9),0) -> 0.81 | D14: =IF(A14<Assumptions!$B$38, MIN(C14+Assumptions!$B$37, 0.95), C14) -> 0.95
A15: =A14+Assumptions!$B$10 -> 130280 | B15: =A15+Assumptions!$B$10-1 -> 135279 | C15: =MAX(Assumptions!$B$6-((ROW()-5)*Assumptions!$B$9),0) -> 0.8 | D15: =IF(A15<Assumptions!$B$38, MIN(C15+Assumptions!$B$37, 0.95), C15) -> 0.95
A16: =A15+Assumptions!$B$10 -> 135280 | B16: =A16+Assumptions!$B$10-1 -> 140279 | C16: =MAX(Assumptions!$B$6-((ROW()-5)*Assumptions!$B$9),0) -> 0.79 | D16: =IF(A16<Assumptions!$B$38, MIN(C16+Assumptions!$B$37, 0.95), C16) -> 0.95
A17: =A16+Assumptions!$B$10 -> 140280 | B17: =A17+Assumptions!$B$10-1 -> 145279 | C17: =MAX(Assumptions!$B$6-((ROW()-5)*Assumptions!$B$9),0) -> 0.78 | D17: =IF(A17<Assumptions!$B$38, MIN(C17+Assumptions!$B$37, 0.95), C17) -> 0.95
A18: =A17+Assumptions!$B$10 -> 145280 | B18: =A18+Assumptions!$B$10-1 -> 150279 | C18: =MAX(Assumptions!$B$6-((ROW()-5)*Assumptions!$B$9),0) -> 0.77 | D18: =IF(A18<Assumptions!$B$38, MIN(C18+Assumptions!$B$37, 0.95), C18) -> 0.95
... A95: =A94+Assumptions!$B$10 -> 530280 | B95: =A95+Assumptions!$B$10-1 -> 535279 | C95: =MAX(Assumptions!$B$6-((ROW()-5)*Assumptions!$B$9),0) -> 0 | D95: =IF(A95<Assumptions!$B$38, MIN(C95+Assumptions!$B$37, 0.95), C95) -> 0
A97: NOTES & LOOKUP REFERENCE
A98: Standard CCS %: | B98: 90% for income ≤$85,279; decreases 1% per $5,000 above threshold; 0% at ≥$535,279
A99: Higher CCS %: | B99: Standard CCS % + 30%, capped at 95%. Applies to 2nd and subsequent children aged ≤5 years
A100: CCS Taper: | B100: 1 percentage point reduction per $5,000 of family income above $85,279
A101: Higher CCS Cap: | B101: Higher CCS ceases when family income ≥ $367,563 (reverts to standard rate)
A102: Source: | B102: Department of Education — education.gov.au/early-childhood/providers/child-care-subsidy
A103: Effective: | B103: FY2025-26, from 7 July 2025
A104: Lookup Formula: | B104: Use INDEX/MATCH or VLOOKUP on column A (Income From) to find CCS % in column C or D

Sheet Sensitivity
A1: CCS INCOME SENSITIVITY ANALYSIS
A2: Shows how CCS % and costs change across income levels (holding all other inputs constant)
A3: ⬅ Back to Inputs
B4: Family Income | C4: Standard CCS % | D4: Higher CCS % | E4: Annual Gross Fees | F4: Annual CCS Paid | G4: Annual Out-of-Pocket | H4: Effective CCS Rate | J4: Family Income | K4: Annual Out-of-Pocket
B5: 50000 | C5: =VLOOKUP(B5,'Rate Tables'!$A$5:$D$95,3,TRUE) -> 0.9 | D5: =VLOOKUP(B5,'Rate Tables'!$A$5:$D$95,4,TRUE) -> 0.95 | E5: =Calculations!$C$46 -> 36660 | F5: =E5*C5*(1-Inputs!$C$6) -> 31344.3 | G5: =E5-F5 -> 5315.7 | H5: =IF(E5=0,"-",F5/E5) -> 0.855 | J5: =B5 -> 50000 | K5: =G5 -> 5315.7
B6: 60000 | C6: =VLOOKUP(B6,'Rate Tables'!$A$5:$D$95,3,TRUE) -> 0.9 | D6: =VLOOKUP(B6,'Rate Tables'!$A$5:$D$95,4,TRUE) -> 0.95 | E6: =Calculations!$C$46 -> 36660 | F6: =E6*C6*(1-Inputs!$C$6) -> 31344.3 | G6: =E6-F6 -> 5315.7 | H6: =IF(E6=0,"-",F6/E6) -> 0.855 | J6: =B6 -> 60000 | K6: =G6 -> 5315.7
B7: 70000 | C7: =VLOOKUP(B7,'Rate Tables'!$A$5:$D$95,3,TRUE) -> 0.9 | D7: =VLOOKUP(B7,'Rate Tables'!$A$5:$D$95,4,TRUE) -> 0.95 | E7: =Calculations!$C$46 -> 36660 | F7: =E7*C7*(1-Inputs!$C$6) -> 31344.3 | G7: =E7-F7 -> 5315.7 | H7: =IF(E7=0,"-",F7/E7) -> 0.855 | J7: =B7 -> 70000 | K7: =G7 -> 5315.7
B8: 80000 | C8: =VLOOKUP(B8,'Rate Tables'!$A$5:$D$95,3,TRUE) -> 0.9 | D8: =VLOOKUP(B8,'Rate Tables'!$A$5:$D$95,4,TRUE) -> 0.95 | E8: =Calculations!$C$46 -> 36660 | F8: =E8*C8*(1-Inputs!$C$6) -> 31344.3 | G8: =E8-F8 -> 5315.7 | H8: =IF(E8=0,"-",F8/E8) -> 0.855 | J8: =B8 -> 80000 | K8: =G8 -> 5315.7
B9: 90000 | C9: =VLOOKUP(B9,'Rate Tables'!$A$5:$D$95,3,TRUE) -> 0.89 | D9: =VLOOKUP(B9,'Rate Tables'!$A$5:$D$95,4,TRUE) -> 0.95 | E9: =Calculations!$C$46 -> 36660 | F9: =E9*C9*(1-Inputs!$C$6) -> 30996.03 | G9: =E9-F9 -> 5663.97 | H9: =IF(E9=0,"-",F9/E9) -> 0.8455 | J9: =B9 -> 90000 | K9: =G9 -> 5663.97
B10: 100000 | C10: =VLOOKUP(B10,'Rate Tables'!$A$5:$D$95,3,TRUE) -> 0.87 | D10: =VLOOKUP(B10,'Rate Tables'!$A$5:$D$95,4,TRUE) -> 0.95 | E10: =Calculations!$C$46 -> 36660 | F10: =E10*C10*(1-Inputs!$C$6) -> 30299.49 | G10: =E10-F10 -> 6360.51 | H10: =IF(E10=0,"-",F10/E10) -> 0.8265 | J10: =B10 -> 100000 | K10: =G10 -> 6360.51
B11: 110000 | C11: =VLOOKUP(B11,'Rate Tables'!$A$5:$D$95,3,TRUE) -> 0.85 | D11: =VLOOKUP(B11,'Rate Tables'!$A$5:$D$95,4,TRUE) -> 0.95 | E11: =Calculations!$C$46 -> 36660 | F11: =E11*C11*(1-Inputs!$C$6) -> 29602.95 | G11: =E11-F11 -> 7057.05 | H11: =IF(E11=0,"-",F11/E11) -> 0.8075 | J11: =B11 -> 110000 | K11: =G11 -> 7057.05
B12: 120000 | C12: =VLOOKUP(B12,'Rate Tables'!$A$5:$D$95,3,TRUE) -> 0.83 | D12: =VLOOKUP(B12,'Rate Tables'!$A$5:$D$95,4,TRUE) -> 0.95 | E12: =Calculations!$C$46 -> 36660 | F12: =E12*C12*(1-Inputs!$C$6) -> 28906.41 | G12: =E12-F12 -> 7753.59 | H12: =IF(E12=0,"-",F12/E12) -> 0.7885 | J12: =B12 -> 120000 | K12: =G12 -> 7753.59
B13: 130000 | C13: =VLOOKUP(B13,'Rate Tables'!$A$5:$D$95,3,TRUE) -> 0.81 | D13: =VLOOKUP(B13,'Rate Tables'!$A$5:$D$95,4,TRUE) -> 0.95 | E13: =Calculations!$C$46 -> 36660 | F13: =E13*C13*(1-Inputs!$C$6) -> 28209.87 | G13: =E13-F13 -> 8450.13 | H13: =IF(E13=0,"-",F13/E13) -> 0.7695 | J13: =B13 -> 130000 | K13: =G13 -> 8450.13
B14: 140000 | C14: =VLOOKUP(B14,'Rate Tables'!$A$5:$D$95,3,TRUE) -> 0.79 | D14: =VLOOKUP(B14,'Rate Tables'!$A$5:$D$95,4,TRUE) -> 0.95 | E14: =Calculations!$C$46 -> 36660 | F14: =E14*C14*(1-Inputs!$C$6) -> 27513.33 | G14: =E14-F14 -> 9146.67 | H14: =IF(E14=0,"-",F14/E14) -> 0.7505 | J14: =B14 -> 140000 | K14: =G14 -> 9146.67
B15: 150000 | C15: =VLOOKUP(B15,'Rate Tables'!$A$5:$D$95,3,TRUE) -> 0.77 | D15: =VLOOKUP(B15,'Rate Tables'!$A$5:$D$95,4,TRUE) -> 0.95 | E15: =Calculations!$C$46 -> 36660 | F15: =E15*C15*(1-Inputs!$C$6) -> 26816.79 | G15: =E15-F15 -> 9843.21 | H15: =IF(E15=0,"-",F15/E15) -> 0.7315 | J15: =B15 -> 150000 | K15: =G15 -> 9843.21
B16: 160000 | C16: =VLOOKUP(B16,'Rate Tables'!$A$5:$D$95,3,TRUE) -> 0.75 | D16: =VLOOKUP(B16,'Rate Tables'!$A$5:$D$95,4,TRUE) -> 0.95 | E16: =Calculations!$C$46 -> 36660 | F16: =E16*C16*(1-Inputs!$C$6) -> 26120.25 | G16: =E16-F16 -> 10539.75 | H16: =IF(E16=0,"-",F16/E16) -> 0.7125 | J16: =B16 -> 160000 | K16: =G16 -> 10539.75
... B55: 550000 | C55: =VLOOKUP(B55,'Rate Tables'!$A$5:$D$95,3,TRUE) -> 0 | D55: =VLOOKUP(B55,'Rate Tables'!$A$5:$D$95,4,TRUE) -> 0 | E55: =Calculations!$C$46 -> 36660 | F55: =E55*C55*(1-Inputs!$C$6) -> 0 | G55: =E55-F55 -> 36660 | H55: =IF(E55=0,"-",F55/E55) -> 0 | J55: =B55 -> 550000 | K55: =G55 -> 36660
B57: KEY FINDINGS
B58: Maximum CCS (90%) applies to family incomes at or below $85,279
B59: CCS reduces by 1% for every $5,000 of income above $85,279
B60: CCS reaches 0% at family income of $535,279 or above
B61: Higher CCS (up to 30% more) applies to 2nd+ children aged 5 or under (income < $367,563)
B62: Yellow highlighted row shows your current family income scenario

Sheet Guide
A1: CCS CALCULATOR — USER GUIDE
A2: Instructions, glossary, and official source references for the Australian Child Care Subsidy Calculator (FY2025-26)
A3: ⬅ Back to Inputs
B4: SECTION 1: HOW TO USE THIS CALCULATOR
B6: Step 1: Enter Family Income | C6: Go to the Inputs tab and enter your combined family income in the yellow-highlighted cell (C5). This is your estimated annual adjusted taxable income for the current financial year.
B8: Step 2: Enter Child Details | C8: For each child in care (up to 6), fill in: Child Name, Age, Care Type (select from dropdown: CBDC, OSHC, FDC, IHC), Hourly Fee Charged by provider, Hours per Week in care, and Days per Week.
B10: Step 3: Review Results | C10: The Quick Results section on the Inputs tab automatically shows your CCS %, hourly rates, weekly costs, and annual out-of-pocket for each child. The Dashboard tab provides visual charts and summaries.
B12: Step 4: Explore Scenarios | C12: Change any input value and all calculations update instantly. Use the Sensitivity tab to see how different income levels affect your CCS and out-of-pocket costs.
B14: Step 5: Understand the Workings | C14: The Calculations tab shows every step of the CCS computation in detail — from income lookup to hourly rate caps to subsidy amounts. The Assumptions tab lists all FY2025-26 parameters with official source references.
B16: Tips | C16: • Only edit yellow-highlighted cells on the Inputs tab • Leave unused children blank • Care type codes: CBDC = Centre-Based Day Care, OSHC = Outside School Hours Care, FDC = Family Day Care, IHC = In-Home Care • Withholding rate defaults to 5% — change in Inputs cell C6 if needed
B18: Important Notes | C18: This calculator provides estimates only. Actual CCS payments are determined by Services Australia (Centrelink) based on your confirmed income, activity test results, and individual circumstances. Always confirm with Services Australia for your official entitlement.
B20: SECTION 2: TAB DESCRIPTIONS
B22: Tab Name | C22: Description
B23: Inputs | C23: Your main data entry point. Enter family income, number of children, each child's details (age, care type, fees, hours). Quick Results section shows per-child and family totals instantly.
B24: Dashboard | C24: Visual summary with key metrics (income, CCS%, annual totals) and 4 charts: cost breakdown pie chart, per-child comparison bar chart, CCS% income sensitivity line chart, and out-of-pocket area chart.
B25: Calculations | C25: Detailed step-by-step workings showing: (1) Input summary, (2) CCS% determination via income lookup, (3) Hourly rate cap application, (4) Subsidy calculation with withholding, (5) Weekly/fortnightly/annual period summaries.
B26: Assumptions | C26: All FY2025-26 CCS parameters: income thresholds, hourly rate caps by care type, activity test hours, 3-Day Guarantee rules, Higher CCS criteria, withholding rate, and ACCS provisions. Each parameter cites its official source.
B27: Rate Tables | C27: Complete CCS lookup engine with 91 income bands ($0 to $535,279 in $5,000 increments). Shows Standard CCS% and Higher CCS% for each band. Used by VLOOKUP formulas in Calculations tab.
B28: Sensitivity | C28: Income sensitivity analysis showing how CCS% and out-of-pocket costs change across 51 income levels ($50k to $550k). Includes comparison of Standard vs Higher CCS rates and charts visualising the impact.
B29: Guide (this tab) | C29: User instructions, glossary of terms, care type definitions, and complete list of official source references with URLs.
B36: SECTION 3: GLOSSARY OF TERMS
B38: Term | C38: Definition
B39: CCS | C39: Child Care Subsidy — the Australian Government payment that helps families with the cost of approved child care. Replaced the previous Child Care Benefit (CCB) and Child Care Rebate (CCR) from July 2018.
B40: CBDC | C40: Centre-Based Day Care — long day care services typically for children 0-5 years before school. Includes preschool/kindergarten programs. Hourly rate cap: $14.63 (below school age) / $12.81 (school age).
B41: OSHC | C41: Outside School Hours Care — before/after school care and vacation care for school-age children. Hourly rate cap: $14.63 (below school age) / $12.81 (school age).
B42: FDC | C42: Family Day Care — care provided in the educator's home for small groups of children. Hourly rate cap: $13.56/hr.
B43: IHC | C43: In-Home Care — care provided in the family's own home by an approved in-home carer. Rate cap of $39.80/hr is per family (not per child). Intended for families with complex needs.
B44: Higher CCS | C44: An additional CCS percentage (up to 30% higher, max 95%) for the second and subsequent children aged 5 years and under in approved child care. Applies to family incomes below $367,563.
B45: Activity Test | C45: Assessment of recognised activities (work, study, volunteering, etc.) undertaken by parents/guardians to determine the maximum subsidised hours per fortnight. Not applicable under 3-Day Guarantee.
B46: 3-Day Guarantee | C46: From 5 January 2026, all families receive a minimum 72 subsidised hours per fortnight (equiv. to 3 days/week) regardless of activity test. Families with >48 hrs recognised activity or First Nations children get 100 hrs/fortnight.
B47: Withholding | C47: A percentage of your CCS held back by Services Australia to reduce the risk of overpayment. Default is 5%. Withheld amounts are reconciled after end of financial year based on actual income. You can set 0%-100%.
B48: ACCS | C48: Additional Child Care Subsidy — extra support for families experiencing financial hardship, transitioning to work, or in temporary financial hardship. ACCS Transition to Work provides 95% subsidy for up to 13 weeks.
B49: Hourly Rate Cap | C49: The maximum hourly fee the government will use to calculate your CCS. If your provider charges more than the cap, you pay the difference. Caps vary by care type and whether the child is school age.
... B55: FY2025-26 | C55: The Australian financial year from 1 July 2025 to 30 June 2026. CCS parameters are updated annually. This calculator uses FY2025-26 rates effective from 7 July 2025.
B57: SECTION 4: OFFICIAL SOURCE REFERENCES
B59: Parameter / Topic | C59: Official Source | D59: URL / Reference
B60: CCS Overview & Eligibility | C60: Services Australia (Centrelink) | D60: https://www.servicesaustralia.gov.au/child-care-subsidy
B61: CCS Percentage Rates by Income | C61: Department of Education | D61: https://www.education.gov.au/early-childhood/child-care-subsidy/child-care-subsidy-percentage-and-income-thresholds
B62: Hourly Rate Caps by Care Type | C62: Department of Education | D62: https://www.education.gov.au/early-childhood/child-care-subsidy/hourly-rate-caps
B63: Activity Test & Recognised Activities | C63: Services Australia | D63: https://www.servicesaustralia.gov.au/activity-test-for-child-care-subsidy
...
