Workbook

Sheet ① Assumptions
A1: AUSTRALIAN CHILD EDUCATION FINANCIAL MODEL
A2: 📋 STEP 1 OF 1: Fill in the blue cells below → then view ② Dashboard for your results → ③ Analysis for detailed breakdowns
A3: LEGEND: | B3: ✎ YOU EDIT THIS COLUMN | C3: ƒx FORMULA | D3: ● FIXED / REFERENCE
A4: SECTION 1: CHILD & GENERAL DETAILS
A5: Child Birth Year | B5: 2024 | D5: ✎ Enter birth year (e.g. 2025)
A6: State | B6: VIC | D6: ✎ VIC or NSW
A7: General Inflation Rate (CPI) | B7: 0.03 | D7: ✎ Annual CPI inflation (e.g. 3%)
A8: Education Inflation Rate | B8: 0.05 | D8: ✎ Education-specific inflation (e.g. 5%)
A10: SECTION 2: SCHOOL PATHWAY
A11: School Type | B11: Public | D11: ✎ Public or Private
A12: Private School Entry Grade | B12: 5 | D12: ✎ Prep, 5, 7, 9, or 12
A13: Selected School (VIC) | B13: Haileybury | D13: ✎ See School Fee Reference tab
A14: Selected School (NSW) | B14: The Scots College | D14: ✎ See School Fee Reference tab
A16: SECTION 3: CHILDCARE (Age 0–4)
A17: Use Childcare? | B17: Yes | D17: ✎ Yes or No
A18: Childcare Start Age | B18: 1 | D18: ✎ Age child starts childcare (0–4)
A19: Childcare End Age | B19: 4 | D19: ✎ Age child ends childcare
A20: Daily Childcare Rate ($) | B20: 169 | D20: ✎ Daily fee (avg $100–$180/day)
A21: Days per Week | B21: 2 | D21: ✎ Days per week (1–5)
A22: CCS Rebate % (Auto from Income) | B22: =IF(B108<=83280,0.9,IF(B108>=533280,0,MAX(0,0.9-((B108-83280)/(533280-83280))*0.9))) -> 0.82656 | D22: ← ƒx Auto-calculated from family income; override below
A23: CCS Override % (Manual) | D23: ✎ Leave blank to use auto-calc; enter 0–0.95 to override
A24: Childcare Weeks per Year | B24: 48 | D24: ✎ Typically 48 weeks (excl. holidays); max 52
A25: Annual Childcare Cost (Gross) | B25: =B20*B21*B24 -> 16224 | D25: ← ƒx Calculated: Daily Rate × Days × Weeks/yr
A26: Annual Childcare Cost (Net of CCS) | B26: =B25*(1-IF(B23<>"",B23,B22)) -> 2813.8906 | D26: ← ƒx Calculated: Gross cost × (1 − effective CCS %)
A28: SECTION 4: BEFORE/AFTER SCHOOL CARE (Age 5–12)
A29: Use Before/After School Care? | B29: Yes | D29: ✎ Yes or No
A30: Daily Rate ($) | B30: 30 | D30: ✎ Per session ($20–$35)
A31: Days per Week | B31: 5 | D31: ✎ Days per week (1–5)
A32: Sessions per Day | B32: 2 | D32: ✎ 1 (before OR after) or 2 (both)
A33: Annual Before/After Care Cost | B33: =B30*B31*B32*40 -> 12000 | D33: ← ƒx Calculated: Rate × Days × Sessions × 40 weeks
A35: SECTION 5: UNIVERSITY
A36: Degree Length (Years) | B36: 3 | D36: ✎ 3 (standard), 4 (Eng/Hons), 5–6 (Med/Law)
A37: School Scholarship % Discount | B37: 0 | D37: ✎ 0% = no scholarship; 10–50% typical bursary
A38: University Scholarship % Discount | B38: 0 | D38: ✎ 0% = no scholarship; 10–50% merit-based
A39: University Type | B39: Domestic | D39: ✎ Domestic or International
A40: HECS Band (if Domestic) | B40: Band 2 | D40: ✎ Band 1 / 2 / 3 / 4 (see Uni Reference)
A41: International Annual Fee ($) | B41: 45000 | D41: ✎ If International ($20k–$50k/yr)
A42: Living Arrangement | B42: At Home | D42: ✎ At Home or Away
A43: Annual Living Cost (if Away) | B43: 22000 | D43: ✎ Rent, food, utilities ($15k–$25k/yr)
A44: Textbooks & Materials (Annual) | B44: 1000 | D44: ✎ Annual ($500–$1,500)
...

Sheet ② Dashboard
B1: 📊 YOUR CHILD EDUCATION COST SUMMARY | H1: Year | I1: Fund Balance ($)
B2: All figures update automatically | ← Change inputs on tab ① Assumptions | → Deep analysis on tab ③ Analysis | H2: =0 -> 0 | I2: ='④ Cash Flow Model'!D35 -> 52369
H3: =1 -> 1 | I3: ='④ Cash Flow Model'!E35 -> 53745.95
B4: PLAN STATUS | E4: YOUR CHOICES | H4: =2 -> 2 | I4: ='④ Cash Flow Model'!F35 -> 55006.146
B5: Total Cost (Birth to Age 21) | C5: ='③ Analysis'!B5 -> 1233062.9 | E5: School | F5: =IF('① Assumptions'!B11="Public","Public School",'① Assumptions'!B13) -> Public School | H5: =3 -> 3 | I5: ='④ Cash Flow Model'!G35 -> 52458.176
B6: That's roughly per year: | C6: =C5/22 -> 56048.313 | E6: School Type | F6: ='① Assumptions'!B11 -> Public | H6: =4 -> 4 | I6: ='④ Cash Flow Model'!H35 -> 53038.384
E7: Private School Entry | F7: =IF('① Assumptions'!B11="Public","N/A",'① Assumptions'!B12) -> N/A | H7: =5 -> 5 | I7: ='④ Cash Flow Model'!I35 -> 31912.853
B8: Your Savings Plan | C8: ='① Assumptions'!B90 -> 50000 | E8: University | F8: ='① Assumptions'!B39&" ("&'① Assumptions'!B40&")" -> Domestic (Band 2) | H8: =6 -> 6 | I8: ='④ Cash Flow Model'!J35 -> 5018.8083
B9: (initial lump sum investment) | E9: Uni Living | F9: ='① Assumptions'!B42 -> At Home | H9: =7 -> 7 | I9: ='④ Cash Flow Model'!K35 -> -24289.135
B10: You also save monthly: | C10: ='① Assumptions'!B91 -> 1000 | E10: Childcare | F10: ='① Assumptions'!B17 -> Yes | H10: =8 -> 8 | I10: ='④ Cash Flow Model'!L35 -> -56257.529
E11: State | F11: ='① Assumptions'!B6 -> VIC | H11: =9 -> 9 | I11: ='④ Cash Flow Model'!M35 -> -88350.345
B12: Funding Gap at Age 21 | C12: ='③ Analysis'!B9 -> -660504.36 | E12: Birth Year | F12: ='① Assumptions'!B5 -> 2024 | H12: =10 -> 10 | I12: ='④ Cash Flow Model'!N35 -> -131771.58
H13: =11 -> 11 | I13: ='④ Cash Flow Model'!O35 -> -174230.03
B14: 💰 WHERE DOES THE MONEY GO? | E14: 🎓 COST BY LIFE STAGE | H14: =12 -> 12 | I14: ='④ Cash Flow Model'!P35 -> -227883.94
B15: Category | C15: 21-Year Total | E15: Life Stage | F15: Total Cost | H15: =13 -> 13 | I15: ='④ Cash Flow Model'!Q35 -> -261538.28
B16: =INDEX('③ Analysis'!A22:A38,MATCH(LARGE('③ Analysis'!B22:B38,1),'③ Analysis'!B22:B38,0)) -> Extra-Curriculars | C16: =LARGE('③ Analysis'!B22:B38,1) -> 207947.54 | E16: 👶 Baby & Toddler (Age 0–4) | F16: =SUM('④ Cash Flow Model'!D31:H31) -> 130320.73 | H16: =14 -> 14 | I16: ='④ Cash Flow Model'!R35 -> -288883.87
B17: =INDEX('③ Analysis'!A22:A38,MATCH(LARGE('③ Analysis'!B22:B38,2),'③ Analysis'!B22:B38,0)) -> Health Insurance | C17: =LARGE('③ Analysis'!B22:B38,2) -> 195265.31 | E17: 🏠 Primary School (Age 5–11) | F17: =SUM('④ Cash Flow Model'!I31:O31) -> 429583.94 | H17: =15 -> 15 | I17: ='④ Cash Flow Model'!S35 -> -320125.02
B18: =INDEX('③ Analysis'!A22:A38,MATCH(LARGE('③ Analysis'!B22:B38,3),'③ Analysis'!B22:B38,0)) -> Before/After School Care | C18: =LARGE('③ Analysis'!B22:B38,3) -> 146248.22 | E18: 📚 Secondary School (Age 12–17) | F18: =SUM('④ Cash Flow Model'!P31:U31) -> 379198.03 | H18: =16 -> 16 | I18: ='④ Cash Flow Model'!T35 -> -357443.35
B19: =INDEX('③ Analysis'!A22:A38,MATCH(LARGE('③ Analysis'!B22:B38,4),'③ Analysis'!B22:B38,0)) -> University Fees | C19: =LARGE('③ Analysis'!B22:B38,4) -> 60854.261 | E19: 🎓 University (Age 18–20) | F19: =SUM('④ Cash Flow Model'!V31:X31) -> 247620.94 | H19: =17 -> 17 | I19: ='④ Cash Flow Model'!U35 -> -398836.18
B20: =INDEX('③ Analysis'!A22:A38,MATCH(LARGE('③ Analysis'!B22:B38,5),'③ Analysis'!B22:B38,0)) -> Car Costs | C20: =LARGE('③ Analysis'!B22:B38,5) -> 46903.531 | E20: 🌟 Post-Uni (Age 21) | F20: ='④ Cash Flow Model'!Y31 -> 46339.232 | H20: =18 -> 18 | I20: ='④ Cash Flow Model'!V35 -> -489440.66
B21: Everything Else | C21: ='③ Analysis'!B41-SUM(C16:C20) -> 575844.02 | E21: TOTAL | F21: =SUM(F16:F20) -> 1233062.9 | H21: =19 -> 19 | I21: ='④ Cash Flow Model'!W35 -> -543276.11
H22: =20 -> 20 | I22: ='④ Cash Flow Model'!X35 -> -612025.68
B23: 💡 WHAT YOU SHOULD KNOW | E23: ✅ QUICK TIPS TO SAVE MONEY | H23: =21 -> 21 | I23: ='④ Cash Flow Model'!Y35 -> -660504.36
B24: =IF(C12<0,"⚠️ Your plan has a funding gap of "&TEXT(-C12,"$#,##0")&". You'll need to save more, invest better, or reduce costs.","✅ Great news! Your plan is fully funded with "&TEXT(C12,"$#,##0")&" to spare.") -> ⚠️ Your plan has a funding gap of $660,504. You'll need to save more, invest better, or reduce costs. | E24: ="1️⃣ Living Costs & Extra-Curriculars are the biggest drivers ("&TEXT(('③ Analysis'!B39+'③ Analysis'!B27)/'③ Analysis'!B41,"0%")&" of total). Review Section 7 & 14 on ① Assumptions." -> 1️⃣ Living Costs & Extra-Curriculars are the biggest drivers (45% of total). Review Section 7 & 14 on ① Assumptions.
B25: =IF('③ Analysis'!B9>=0,"✅ Your plan is on track — the fund is projected to be fully funded at Age 21.","💵 Even at your current "&TEXT('① Assumptions'!B93,"$#,##0")&"/year contribution, the plan has a "&TEXT(ABS('③ Analysis'!B9),"$#,##0")&" shortfall. The gap is driven by costs compounding faster than investment returns — try increasing contributions or reducing costs on tab ① Assumptions.") -> 💵 Even at your current $12,000/year contribution, the plan has a $660,504 shortfall. The gap is driven by costs compounding faster than investment returns — try increasing contributions or reducing costs on tab ① Assumptions. | E25: 2️⃣ Switch to Public school or delay Private entry to Year 7/9 — saves years of compounding school fees. Change on ① Assumptions (Section 2).
B26: ="🏦 Your $"&TEXT('① Assumptions'!B90,"#,##0")&" lump sum grows to ~$"&TEXT('① Assumptions'!B90*(1+'① Assumptions'!B97)^21,"#,##0")&" over 21 years at "&TEXT('① Assumptions'!B97,"0.0%")&" net return ("&TEXT('① Assumptions'!B95,"0%")&" gross, "&TEXT('① Assumptions'!B96,"0%")&" tax)." -> 🏦 Your $50,000 lump sum grows to ~$115,094 over 21 years at 4.1% net return (6% gross, 33% tax). | E26: 3️⃣ Increase your monthly contribution by even $200 — it compounds significantly over 21 years. Update on ① Assumptions (Section 11). | H26: Year | I26: Total Costs ($) | J26: Total Income ($)
B27: ="📈 Your most expensive life stage is "&INDEX(E16:E20,MATCH(MAX(F16:F20),F16:F20,0))&" at "&TEXT(MAX(F16:F20),"$#,##0")&" — "&TEXT(MAX(F16:F20)/C5,"0%")&" of your total 21-year spend." -> 📈 Your most expensive life stage is 🏠 Primary School (Age 5–11) at $429,584 — 35% of your total 21-year spend. | E27: 4️⃣ Check your CCS rebate % on ① Assumptions (B22) — many families under-claim the Child Care Subsidy. | H27: =0 -> 0 | I27: ='④ Cash Flow Model'!D26 -> 0 | J27: ='④ Cash Flow Model'!D31 -> 21000
B28: ="👨‍👩‍👧 Government benefits cover $"&TEXT('③ Analysis'!B7,"#,##0")&" of your costs over 21 years (FTB + CCS)." -> 👨‍👩‍👧 Government benefits cover $296,693 of your costs over 21 years (FTB + CCS). | E28: 5️⃣ Use HECS-HELP for uni (Band 1–2) — it’s interest-free and indexed to CPI only, not education inflation. Update on ① Assumptions (Section 5). | H28: =1 -> 1 | I28: ='④ Cash Flow Model'!E26 -> 0 | J28: ='④ Cash Flow Model'!E31 -> 24874.064
B29: ="📊 "&INDEX('③ Analysis'!A22:A40,MATCH(MAX('③ Analysis'!B22:B40),'③ Analysis'!B22:B40,0))&" is your biggest cost at "&TEXT(MAX('③ Analysis'!B22:B40),"$#,##0")&" ("&TEXT(MAX('③ Analysis'!C22:C40),"0%")&" of total) — review this category on tab ① Assumptions." -> 📊 Living Costs is your biggest cost at $348,455 (28% of total) — review this category on tab ① Assumptions. | H29: =2 -> 2 | I29: ='④ Cash Flow Model'!F26 -> 0 | J29: ='④ Cash Flow Model'!F31 -> 25832.588
B30: ="⭐ Education inflation ("&TEXT('① Assumptions'!B8,"0%")&"/yr) is higher than general CPI ("&TEXT('① Assumptions'!B7,"0%")&"/yr) — costs rise faster than everything else." -> ⭐ Education inflation (5%/yr) is higher than general CPI (3%/yr) — costs rise faster than everything else. | H30: =3 -> 3 | I30: ='④ Cash Flow Model'!G26 -> 0 | J30: ='④ Cash Flow Model'!G31 -> 30503.547
H31: =4 -> 4 | I31: ='④ Cash Flow Model'!H26 -> 0 | J31: ='④ Cash Flow Model'!H31 -> 28110.533
B32: 📖 HOW TO USE THIS MODEL | H32: =5 -> 5 | I32: ='④ Cash Flow Model'!I26 -> 0 | J32: ='④ Cash Flow Model'!I31 -> 50705.609
B33: 1. Go to the Assumptions tab — all the blue cells are things you can change. | E33: 3. This dashboard updates instantly when you change anything. | H33: =6 -> 6 | I33: ='④ Cash Flow Model'!J26 -> 0 | J33: ='④ Cash Flow Model'!J31 -> 56512.759
B34: 2. Key choices: Public vs Private school, which school, university type. | E34: 4. For deeper analysis, see the ③ Analysis tab (IRR, sensitivity, break-even) and ④ Cash Flow Model (year-by-year detail). | H34: =7 -> 7 | I34: ='④ Cash Flow Model'!K26 -> 0 | J34: ='④ Cash Flow Model'!K31 -> 58760.992
B35: Use the dropdown menus — just click the cells and pick from the list. | E35: They have more detail: year-by-year costs, sensitivity tables, break-even analysis. | H35: =8 -> 8 | I35: ='④ Cash Flow Model'!L26 -> 0 | J35: ='④ Cash Flow Model'!L31 -> 61106.325
H36: =9 -> 9 | I36: ='④ Cash Flow Model'!M26 -> 0 | J36: ='④ Cash Flow Model'!M31 -> 60813.252
H37: =10 -> 10 | I37: ='④ Cash Flow Model'!N26 -> 0 | J37: ='④ Cash Flow Model'!N31 -> 71751.03
H38: =11 -> 11 | I38: ='④ Cash Flow Model'!O26 -> 0 | J38: ='④ Cash Flow Model'!O31 -> 69933.972
H39: =12 -> 12 | I39: ='④ Cash Flow Model'!P26 -> 0 | J39: ='④ Cash Flow Model'!P31 -> 80351.864
H40: =13 -> 13 | I40: ='④ Cash Flow Model'!Q26 -> 0 | J40: ='④ Cash Flow Model'!Q31 -> 61004.764
...

Sheet ③ Analysis
A1: IRR & DASHBOARD
A2: All outputs are formula-driven | ← Change inputs on tab ① Assumptions | View summary on tab ② Dashboard
A4: KEY METRICS
A5: Total 21-Year Costs | B5: =SUM('④ Cash Flow Model'!D31:Y31) -> 1233062.9 | E5: The rate of return needed to fully fund the plan (Fund Balance = 0 at Year 21)
A6: Total Contributions + Govt Benefits (Lump Sum + Regular + Benefits) | B6: =SUM('④ Cash Flow Model'!D8:Y8)+SUM('④ Cash Flow Model'!D7:Y7) -> 734639.45
A7: Total Government Benefits | B7: =SUM('④ Cash Flow Model'!D7:Y7) -> 296692.63 | E7: Year | F7: Net Cash Flow (excl. returns) | G7: Description
A8: Total Investment Returns | B8: =SUM('④ Cash Flow Model'!D9:Y9) -> -162080.93 | E8: 0 | F8: ='④ Cash Flow Model'!D8+'④ Cash Flow Model'!D7-'④ Cash Flow Model'!D31 -> 52369 | G8: Initial investment + Year 0 net
A9: Final Fund Balance (Year 21) | B9: ='④ Cash Flow Model'!Y35 -> -660504.36 | E9: 1 | F9: ='④ Cash Flow Model'!E8+'④ Cash Flow Model'!E7-'④ Cash Flow Model'!E31 -> -743.99434 | G9: Year 1 net (excl. returns)
A10: Total Costs in Today's Dollars (PV) | B10: {=SUMPRODUCT('④ Cash Flow Model'!D31:Y31/(1+'① Assumptions'!B7)^'④ Cash Flow Model'!D3:Y3)} -> 875013.23 | E10: 2 | F10: ='④ Cash Flow Model'!F8+'④ Cash Flow Model'!F7-'④ Cash Flow Model'!F31 -> -916.51546
A11: Effective Net Return (after tax) | B11: ='① Assumptions'!B97 -> 0.0405 | E11: 3 | F11: ='④ Cash Flow Model'!G8+'④ Cash Flow Model'!G7-'④ Cash Flow Model'!G31 -> -4775.719
E12: 2 | F12: ='④ Cash Flow Model'!H8+'④ Cash Flow Model'!H7-'④ Cash Flow Model'!H31 -> -1544.3473 | G12: Year 4 net (excl. returns)
A13: Initial Lump Sum | B13: ='① Assumptions'!B90 -> 50000 | E13: 3 | F13: ='④ Cash Flow Model'!I8+'④ Cash Flow Model'!I7-'④ Cash Flow Model'!I31 -> -23273.586 | G13: Year 5 net (excl. returns)
A14: Annual Contribution (Year 0) | B14: ='① Assumptions'!B93 -> 12000 | E14: 4 | F14: ='④ Cash Flow Model'!J8+'④ Cash Flow Model'!J7-'④ Cash Flow Model'!J31 -> -28186.515 | G14: Year 6 net (excl. returns)
A15: Assumed Rate of Return | B15: ='① Assumptions'!B95 -> 0.06 | E15: 5 | F15: ='④ Cash Flow Model'!K8+'④ Cash Flow Model'!K7-'④ Cash Flow Model'!K31 -> -29511.205 | G15: Year 7 net (excl. returns)
A16: General Inflation (CPI) | B16: ='① Assumptions'!B7 -> 0.03 | E16: 6 | F16: ='④ Cash Flow Model'!L8+'④ Cash Flow Model'!L7-'④ Cash Flow Model'!L31 -> -30902.708 | G16: Year 8 net (excl. returns)
A17: Education Inflation | B17: ='① Assumptions'!B8 -> 0.05 | E17: 7 | F17: ='④ Cash Flow Model'!M8+'④ Cash Flow Model'!M7-'④ Cash Flow Model'!M31 -> -29624.517 | G17: Year 9 net (excl. returns)
A18: ="⚡ KEY INSIGHT: With current assumptions ("&'① Assumptions'!B13&" private from Grade "&TEXT('① Assumptions'!B12,"0")&", $"&TEXT('① Assumptions'!B90/1000,"0")&"k lump + $"&TEXT('① Assumptions'!B93/1000,"0")&"k/yr contributions, "&TEXT('① Assumptions'!B95,"0%")&" gross / "&TEXT('① Assumptions'!B97,"0.0%")&" net return)," -> ⚡ KEY INSIGHT: With current assumptions (Haileybury private from Grade 5, $50k lump + $12k/yr contributions, 6% gross / 4.1% net return), | E18: 8 | F18: ='④ Cash Flow Model'!N8+'④ Cash Flow Model'!N7-'④ Cash Flow Model'!N31 -> -39544.859 | G18: Year 10 net (excl. returns)
A19: =" the plan has a $"&TEXT(ABS('④ Cash Flow Model'!Y35)/1000000,"0.0")&"M "&IF('④ Cash Flow Model'!Y35<0,"shortfall","surplus")&". Try adjusting school type, entry grade, or contributions." -> the plan has a $0.7M shortfall. Try adjusting school type, entry grade, or contributions. | E19: 9 | F19: ='④ Cash Flow Model'!O8+'④ Cash Flow Model'!O7-'④ Cash Flow Model'!O31 -> -36676.981 | G19: Year 11 net (excl. returns)
A20: COST BREAKDOWN BY CATEGORY | F20: ='④ Cash Flow Model'!P8+'④ Cash Flow Model'!P7-'④ Cash Flow Model'!P31 -> -46009.565 | G20: Year 12 net (excl. returns)
A21: Category | B21: 21-Year Total | C21: % of Total | E21: 11 | F21: ='④ Cash Flow Model'!Q8+'④ Cash Flow Model'!Q7-'④ Cash Flow Model'!Q31 -> -23655.934 | G21: Year 13 net (excl. returns)
A22: Childcare | B22: =SUM('④ Cash Flow Model'!D12:Y12) -> 12734.631 | C22: =IF(B$41=0,0,B22/B$41) -> 0.010327641 | E22: 12 | F22: ='④ Cash Flow Model'!R8+'④ Cash Flow Model'!R7-'④ Cash Flow Model'!R31 -> -15870.591 | G22: Year 14 net (excl. returns)
A23: Before/After School Care | B23: =SUM('④ Cash Flow Model'!D13:Y13) -> 146248.22 | C23: =IF(B$41=0,0,B23/B$41) -> 0.11860565 | E23: 13 | F23: ='④ Cash Flow Model'!S8+'④ Cash Flow Model'!S7-'④ Cash Flow Model'!S31 -> -18566.372 | G23: Year 15 net (excl. returns)
A24: School Fees | B24: =SUM('④ Cash Flow Model'!D14:Y14) -> 14967.954 | C24: =IF(B$41=0,0,B24/B$41) -> 0.012138841 | E24: 14 | F24: ='④ Cash Flow Model'!T8+'④ Cash Flow Model'!T7-'④ Cash Flow Model'!T31 -> -23272.846 | G24: Year 16 net (excl. returns)
A25: Uniforms | B25: =SUM('④ Cash Flow Model'!D15:Y15) -> 27157.949 | C25: =IF(B$41=0,0,B25/B$41) -> 0.022024789 | E25: 15 | F25: ='④ Cash Flow Model'!U8+'④ Cash Flow Model'!U7-'④ Cash Flow Model'!U31 -> -25710.001 | G25: Year 17 net (excl. returns)
A26: Camps & Excursions | B26: =SUM('④ Cash Flow Model'!D16:Y16) -> 18105.3 | C26: =IF(B$41=0,0,B26/B$41) -> 0.014683192 | E26: 16 | F26: ='④ Cash Flow Model'!V8+'④ Cash Flow Model'!V7-'④ Cash Flow Model'!V31 -> -73105.544 | G26: Year 18 net (excl. returns)
A27: Extra-Curriculars | B27: =SUM('④ Cash Flow Model'!D17:Y17) -> 207947.54 | C27: =IF(B$41=0,0,B27/B$41) -> 0.16864309 | E27: 17 | F27: ='④ Cash Flow Model'!W8+'④ Cash Flow Model'!W7-'④ Cash Flow Model'!W31 -> -32361.238 | G27: Year 19 net (excl. returns)
A28: Technology | B28: =SUM('④ Cash Flow Model'!D18:Y18) -> 17964.719 | C28: =IF(B$41=0,0,B28/B$41) -> 0.014569183 | E28: 18 | F28: ='④ Cash Flow Model'!X8+'④ Cash Flow Model'!X7-'④ Cash Flow Model'!X31 -> -44913.332 | G28: Year 20 net (excl. returns)
A29: Health Insurance | B29: =SUM('④ Cash Flow Model'!D19:Y19) -> 195265.31 | C29: =IF(B$41=0,0,B29/B$41) -> 0.15835795 | E29: 19 | F29: ='④ Cash Flow Model'!Y8+'④ Cash Flow Model'!Y7-'④ Cash Flow Model'!Y31 -> -21626.054 | G29: Year 21 net (excl. returns)
A30: Orthodontics | B30: =SUM('④ Cash Flow Model'!D20:Y20) -> 10130.031 | C30: =IF(B$41=0,0,B30/B$41) -> 0.0082153403 | E30: 20
A31: Allied Health | B31: =SUM('④ Cash Flow Model'!D21:Y21) -> 14136.412 | C31: =IF(B$41=0,0,B31/B$41) -> 0.01146447 | E31: 21
A32: Driving Lessons | B32: =SUM('④ Cash Flow Model'!D22:Y22) -> 2407.0597 | C32: =IF(B$41=0,0,B32/B$41) -> 0.0019520981
A33: Car Costs | B33: =SUM('④ Cash Flow Model'!D23:Y23) -> 46903.531 | C33: =IF(B$41=0,0,B33/B$41) -> 0.038038231 | E33: REQUIRED RATE OF RETURN (IRR) | F33: =IFERROR(IRR(F8:F29),"N/A — Costs exceed all funding") -> 0.24771804
A34: Gap Year | B34: =SUM('④ Cash Flow Model'!D24:Y24) -> 0 | C34: =IF(B$41=0,0,B34/B$41) -> 0 | E34: Interpretation: | F34: This is the annual investment return needed to make Fund Balance = $0 at Year 21
A35: University Fees | B35: =SUM('④ Cash Flow Model'!D25:Y25) -> 60854.261 | C35: =IF(B$41=0,0,B35/B$41) -> 0.049352115
A36: University Living Costs | B36: =SUM('④ Cash Flow Model'!D26:Y26) -> 0 | C36: =IF(B$41=0,0,B36/B$41) -> 0
A37: Textbooks & Materials | B37: =SUM('④ Cash Flow Model'!D27:Y27) -> 5262.0503 | C37: =IF(B$41=0,0,B37/B$41) -> 0.0042674631
A38: Life Insurance | B38: =SUM('④ Cash Flow Model'!D28:Y28) -> 45805.17 | C38: =IF(B$41=0,0,B38/B$41) -> 0.037147473
A39: Living Costs | B39: =SUM('④ Cash Flow Model'!D29:Y29) -> 348455.46 | C39: =IF(B$41=0,0,B39/B$41) -> 0.28259343
A40: Contingency Buffer | B40: =SUM('④ Cash Flow Model'!D30:Y30) -> 58717.28 | C40: =IF(B$41=0,0,B40/B$41) -> 0.047619048
A41: TOTAL COSTS | B41: =SUM(B22:B40) -> 1233062.9 | C41: =SUM(C22:C40) -> 1
...

Sheet ④ Cash Flow Model
A1: COST OF CHILD — 21-YEAR CASH FLOW PROJECTION
A2: ="All values are formula-driven from ① Assumptions | Total Costs: "&TEXT('④ Cash Flow Model'!Z31,"$#,##0")&" | Total Income: "&TEXT('④ Cash Flow Model'!Z10,"$#,##0")&" | Net Position: "&TEXT('④ Cash Flow Model'!Z33,"$#,##0") -> All values are formula-driven from ① Assumptions | Total Costs: $1,233,063 | Total Income: $572,559 | Net Position: -$660,504
A3: Category | B3: Section | C3: Line Item | D3: 0 | E3: 1 | F3: 2 | G3: 3 | H3: 4 | I3: 5 | J3: 6 | K3: 7 | L3: 8 | M3: 9 | N3: 10 | O3: 11 | P3: 12 | Q3: 13 | R3: 14 | S3: 15 | T3: 16 | U3: 17 | V3: 18 | W3: 19 | X3: 20 | Y3: 21 | Z3: TOTALS
C4: Child Age | D4: 0 | E4: 1 | F4: 2 | G4: 3 | H4: 4 | I4: 5 | J4: 6 | K4: 7 | L4: 8 | M4: 9 | N4: 10 | O4: 11 | P4: 12 | Q4: 13 | R4: 14 | S4: 15 | T4: 16 | U4: 17 | V4: 18 | W4: 19 | X4: 20 | Y4: 21
C5: School Grade | D5: Pre-School | E5: Pre-School | F5: Pre-School | G5: Pre-School | H5: Pre-School | I5: Prep | J5: Grade 1 | K5: Grade 2 | L5: Grade 3 | M5: Grade 4 | N5: Grade 5 | O5: Grade 6 | P5: Year 7 | Q5: Year 8 | R5: Year 9 | S5: Year 10 | T5: Year 11 | U5: Year 12 | V5: Uni Year 1 | W5: Uni Year 2 | X5: Uni Year 3 | Y5: Post-Uni
A6: INCOME
A7: 🏛️ Govt Benefits | B7: Income | C7: Govt Benefits | D7: =IF('① Assumptions'!$B$107="Yes",(IF(D$4<=12,IF(D$4<='① Assumptions'!$B$113,'① Assumptions'!$B$109,0),IF(D$4<='① Assumptions'!$B$113,'① Assumptions'!$B$110,0))+IF(D$4<='① Assumptions'!$B$113,'① Assumptions'!$B$112,0)+IF(D$4<='① Assumptions'!$B$114,'① Assumptions'!$B$111,0))*(1+'① Assumptions'!$B$7)^D$3,0) -> 11369 | E7: =IF('① Assumptions'!$B$107="Yes",(IF(E$4<=12,IF(E$4<='① Assumptions'!$B$113,'① Assumptions'!$B$109,0),IF(E$4<='① Assumptions'!$B$113,'① Assumptions'!$B$110,0))+IF(E$4<='① Assumptions'!$B$113,'① Assumptions'!$B$112,0)+IF(E$4<='① Assumptions'!$B$114,'① Assumptions'!$B$111,0))*(1+'① Assumptions'!$B$7)^E$3,0) -> 11710.07 | F7: =IF('① Assumptions'!$B$107="Yes",(IF(F$4<=12,IF(F$4<='① Assumptions'!$B$113,'① Assumptions'!$B$109,0),IF(F$4<='① Assumptions'!$B$113,'① Assumptions'!$B$110,0))+IF(F$4<='① Assumptions'!$B$113,'① Assumptions'!$B$112,0)+IF(F$4<='① Assumptions'!$B$114,'① Assumptions'!$B$111,0))*(1+'① Assumptions'!$B$7)^F$3,0) -> 12061.372 | G7: =IF('① Assumptions'!$B$107="Yes",(IF(G$4<=12,IF(G$4<='① Assumptions'!$B$113,'① Assumptions'!$B$109,0),IF(G$4<='① Assumptions'!$B$113,'① Assumptions'!$B$110,0))+IF(G$4<='① Assumptions'!$B$113,'① Assumptions'!$B$112,0)+IF(G$4<='① Assumptions'!$B$114,'① Assumptions'!$B$111,0))*(1+'① Assumptions'!$B$7)^G$3,0) -> 12423.213 | H7: =IF('① Assumptions'!$B$107="Yes",(IF(H$4<=12,IF(H$4<='① Assumptions'!$B$113,'① Assumptions'!$B$109,0),IF(H$4<='① Assumptions'!$B$113,'① Assumptions'!$B$110,0))+IF(H$4<='① Assumptions'!$B$113,'① Assumptions'!$B$112,0)+IF(H$4<='① Assumptions'!$B$114,'① Assumptions'!$B$111,0))*(1+'① Assumptions'!$B$7)^H$3,0) -> 12795.91 | I7: =IF('① Assumptions'!$B$107="Yes",(IF(I$4<=12,IF(I$4<='① Assumptions'!$B$113,'① Assumptions'!$B$109,0),IF(I$4<='① Assumptions'!$B$113,'① Assumptions'!$B$110,0))+IF(I$4<='① Assumptions'!$B$113,'① Assumptions'!$B$112,0)+IF(I$4<='① Assumptions'!$B$114,'① Assumptions'!$B$111,0))*(1+'① Assumptions'!$B$7)^I$3,0) -> 13179.787 | J7: =IF('① Assumptions'!$B$107="Yes",(IF(J$4<=12,IF(J$4<='① Assumptions'!$B$113,'① Assumptions'!$B$109,0),IF(J$4<='① Assumptions'!$B$113,'① Assumptions'!$B$110,0))+IF(J$4<='① Assumptions'!$B$113,'① Assumptions'!$B$112,0)+IF(J$4<='① Assumptions'!$B$114,'① Assumptions'!$B$111,0))*(1+'① Assumptions'!$B$7)^J$3,0) -> 13575.181 | K7: =IF('① Assumptions'!$B$107="Yes",(IF(K$4<=12,IF(K$4<='① Assumptions'!$B$113,'① Assumptions'!$B$109,0),IF(K$4<='① Assumptions'!$B$113,'① Assumptions'!$B$110,0))+IF(K$4<='① Assumptions'!$B$113,'① Assumptions'!$B$112,0)+IF(K$4<='① Assumptions'!$B$114,'① Assumptions'!$B$111,0))*(1+'① Assumptions'!$B$7)^K$3,0) -> 13982.436 | ... Y7: =IF('① Assumptions'!$B$107="Yes",(IF(Y$4<=12,IF(Y$4<='① Assumptions'!$B$113,'① Assumptions'!$B$109,0),IF(Y$4<='① Assumptions'!$B$113,'① Assumptions'!$B$110,0))+IF(Y$4<='① Assumptions'!$B$113,'① Assumptions'!$B$112,0)+IF(Y$4<='① Assumptions'!$B$114,'① Assumptions'!$B$111,0))*(1+'① Assumptions'!$B$7)^Y$3,0) -> 0 | Z7: =SUM(D7:Y7) -> 296692.63
A8: 💰 Contributions | B8: Income | C8: Contributions | D8: ='① Assumptions'!$B$90+'① Assumptions'!$B$93 -> 62000 | E8: ='① Assumptions'!$B$93*(1+'① Assumptions'!$B$94)^E$3 -> 12420 | F8: ='① Assumptions'!$B$93*(1+'① Assumptions'!$B$94)^F$3 -> 12854.7 | G8: ='① Assumptions'!$B$93*(1+'① Assumptions'!$B$94)^G$3 -> 13304.614 | H8: ='① Assumptions'!$B$93*(1+'① Assumptions'!$B$94)^H$3 -> 13770.276 | I8: ='① Assumptions'!$B$93*(1+'① Assumptions'!$B$94)^I$3 -> 14252.236 | J8: ='① Assumptions'!$B$93*(1+'① Assumptions'!$B$94)^J$3 -> 14751.064 | K8: ='① Assumptions'!$B$93*(1+'① Assumptions'!$B$94)^K$3 -> 15267.351 | L8: ='① Assumptions'!$B$93*(1+'① Assumptions'!$B$94)^L$3 -> 15801.708 | ... Y8: ='① Assumptions'!$B$93*(1+'① Assumptions'!$B$94)^Y$3 -> 24713.178 | Z8: =SUM(D8:Y8) -> 437946.83
A9: 📈 Investment Return | B9: Income | C9: Investment Return | D9: 0 | E9: =IF(D$35>=0,D$35*'① Assumptions'!$B$97,D$35*'① Assumptions'!$B$105) -> 2120.9445 | F9: =IF(E$35>=0,E$35*'① Assumptions'!$B$97,E$35*'① Assumptions'!$B$105) -> 2176.711 | G9: =IF(F$35>=0,F$35*'① Assumptions'!$B$97,F$35*'① Assumptions'!$B$105) -> 2227.7489 | H9: =IF(G$35>=0,G$35*'① Assumptions'!$B$97,G$35*'① Assumptions'!$B$105) -> 2124.5561 | I9: =IF(H$35>=0,H$35*'① Assumptions'!$B$97,H$35*'① Assumptions'!$B$105) -> 2148.0546 | J9: =IF(I$35>=0,I$35*'① Assumptions'!$B$97,I$35*'① Assumptions'!$B$105) -> 1292.4705 | K9: =IF(J$35>=0,J$35*'① Assumptions'!$B$97,J$35*'① Assumptions'!$B$105) -> 203.26173 | L9: =IF(K$35>=0,K$35*'① Assumptions'!$B$97,K$35*'① Assumptions'!$B$105) -> -1065.6858 | ... Y9: =IF(X$35>=0,X$35*'① Assumptions'!$B$97,X$35*'① Assumptions'!$B$105) -> -26852.627 | Z9: =SUM(D9:Y9) -> -162080.93
A10: ∑ TOTAL INCOME | B10: Income | C10: TOTAL INCOME | D10: =D$7+D$8+D$9 -> 73369 | E10: =E$7+E$8+E$9 -> 26251.015 | F10: =F$7+F$8+F$9 -> 27092.783 | G10: =G$7+G$8+G$9 -> 27955.577 | H10: =H$7+H$8+H$9 -> 28690.742 | I10: =I$7+I$8+I$9 -> 29580.077 | J10: =J$7+J$8+J$9 -> 29618.715 | K10: =K$7+K$8+K$9 -> 29453.049 | ... Y10: =Y$7+Y$8+Y$9 -> -2139.4489 | Z10: =SUM(D10:Y10) -> 572558.52
A11: COSTS
A12: 👶 Childcare | B12: Costs | C12: Childcare | D12: =IF(AND('① Assumptions'!$B$17="Yes",D$4>='① Assumptions'!$B$18,D$4<='① Assumptions'!$B$19),'① Assumptions'!$B$26*(1+'① Assumptions'!$B$49)^D$3,0) -> 0 | E12: =IF(AND('① Assumptions'!$B$17="Yes",E$4>='① Assumptions'!$B$18,E$4<='① Assumptions'!$B$19),'① Assumptions'!$B$26*(1+'① Assumptions'!$B$49)^E$3,0) -> 2954.5851 | F12: =IF(AND('① Assumptions'!$B$17="Yes",F$4>='① Assumptions'!$B$18,F$4<='① Assumptions'!$B$19),'① Assumptions'!$B$26*(1+'① Assumptions'!$B$49)^F$3,0) -> 3102.3143 | G12: =IF(AND('① Assumptions'!$B$17="Yes",G$4>='① Assumptions'!$B$18,G$4<='① Assumptions'!$B$19),'① Assumptions'!$B$26*(1+'① Assumptions'!$B$49)^G$3,0) -> 3257.4301 | H12: =IF(AND('① Assumptions'!$B$17="Yes",H$4>='① Assumptions'!$B$18,H$4<='① Assumptions'!$B$19),'① Assumptions'!$B$26*(1+'① Assumptions'!$B$49)^H$3,0) -> 3420.3016 | I12: =IF(AND('① Assumptions'!$B$17="Yes",I$4>='① Assumptions'!$B$18,I$4<='① Assumptions'!$B$19),'① Assumptions'!$B$26*(1+'① Assumptions'!$B$49)^I$3,0) -> 0 | J12: =IF(AND('① Assumptions'!$B$17="Yes",J$4>='① Assumptions'!$B$18,J$4<='① Assumptions'!$B$19),'① Assumptions'!$B$26*(1+'① Assumptions'!$B$49)^J$3,0) -> 0 | K12: =IF(AND('① Assumptions'!$B$17="Yes",K$4>='① Assumptions'!$B$18,K$4<='① Assumptions'!$B$19),'① Assumptions'!$B$26*(1+'① Assumptions'!$B$49)^K$3,0) -> 0 | ... Y12: =IF(AND('① Assumptions'!$B$17="Yes",Y$4>='① Assumptions'!$B$18,Y$4<='① Assumptions'!$B$19),'① Assumptions'!$B$26*(1+'① Assumptions'!$B$49)^Y$3,0) -> 0 | Z12: =SUM(D12:Y12) -> 12734.631
A13: 🏫 Before / After Care | B13: Costs | C13: Before/After Care | D13: =IF(AND('① Assumptions'!$B$29="Yes",D$4>=5,D$4<=12),'① Assumptions'!$B$33*(1+'① Assumptions'!$B$49)^D$3,0) -> 0 | E13: =IF(AND('① Assumptions'!$B$29="Yes",E$4>=5,E$4<=12),'① Assumptions'!$B$33*(1+'① Assumptions'!$B$49)^E$3,0) -> 0 | F13: =IF(AND('① Assumptions'!$B$29="Yes",F$4>=5,F$4<=12),'① Assumptions'!$B$33*(1+'① Assumptions'!$B$49)^F$3,0) -> 0 | G13: =IF(AND('① Assumptions'!$B$29="Yes",G$4>=5,G$4<=12),'① Assumptions'!$B$33*(1+'① Assumptions'!$B$49)^G$3,0) -> 0 | H13: =IF(AND('① Assumptions'!$B$29="Yes",H$4>=5,H$4<=12),'① Assumptions'!$B$33*(1+'① Assumptions'!$B$49)^H$3,0) -> 0 | I13: =IF(AND('① Assumptions'!$B$29="Yes",I$4>=5,I$4<=12),'① Assumptions'!$B$33*(1+'① Assumptions'!$B$49)^I$3,0) -> 15315.379 | J13: =IF(AND('① Assumptions'!$B$29="Yes",J$4>=5,J$4<=12),'① Assumptions'!$B$33*(1+'① Assumptions'!$B$49)^J$3,0) -> 16081.148 | K13: =IF(AND('① Assumptions'!$B$29="Yes",K$4>=5,K$4<=12),'① Assumptions'!$B$33*(1+'① Assumptions'!$B$49)^K$3,0) -> 16885.205 | ... Y13: =IF(AND('① Assumptions'!$B$29="Yes",Y$4>=5,Y$4<=12),'① Assumptions'!$B$33*(1+'① Assumptions'!$B$49)^Y$3,0) -> 0 | Z13: =SUM(D13:Y13) -> 146248.22
A14: 🏫 School Fees | B14: Costs | C14: School Fees | D14: =IF(OR(D$4<5,D$4>17),0,IF('① Assumptions'!$B$11="Public",IF(D$4<=11,'⑤ School Fees'!$B$18,'⑤ School Fees'!$C$18)*(1+'① Assumptions'!$B$8)^D$3,IF(D$4<IF('① Assumptions'!$B$12="Prep",5,IF('① Assumptions'!$B$12=5,10,IF('① Assumptions'!$B$12=7,12,IF('① Assumptions'!$B$12=9,14,17)))),IF(D$4<=11,'⑤ School Fees'!$B$18,'⑤ School Fees'!$C$18)*(1+'① Assumptions'!$B$8)^D$3,IF('① Assumptions'!$B$6="VIC",IF(D$4<=11,VLOOKUP('① Assumptions'!$B$13,'⑤ School Fees'!$A$6:$C$15,2,FALSE),VLOOKUP('① Assumptions'!$B$13,'⑤ School Fees'!$A$6:$C$15,3,FALSE)),IF(D$4<=11,VLOOKUP('① Assumptions'!$B$14,'⑤ School Fees'!$A$22:$C$31,2,FALSE),VLOOKUP('① Assumptions'!$B$14,'⑤ School Fees'!$A$22:$C$31,3,FALSE)))*(1-'① Assumptions'!$B$37)*(1+'① Assumptions'!$B$8)^D$3))) -> 0 | E14: =IF(OR(E$4<5,E$4>17),0,IF('① Assumptions'!$B$11="Public",IF(E$4<=11,'⑤ School Fees'!$B$18,'⑤ School Fees'!$C$18)*(1+'① Assumptions'!$B$8)^E$3,IF(E$4<IF('① Assumptions'!$B$12="Prep",5,IF('① Assumptions'!$B$12=5,10,IF('① Assumptions'!$B$12=7,12,IF('① Assumptions'!$B$12=9,14,17)))),IF(E$4<=11,'⑤ School Fees'!$B$18,'⑤ School Fees'!$C$18)*(1+'① Assumptions'!$B$8)^E$3,IF('① Assumptions'!$B$6="VIC",IF(E$4<=11,VLOOKUP('① Assumptions'!$B$13,'⑤ School Fees'!$A$6:$C$15,2,FALSE),VLOOKUP('① Assumptions'!$B$13,'⑤ School Fees'!$A$6:$C$15,3,FALSE)),IF(E$4<=11,VLOOKUP('① Assumptions'!$B$14,'⑤ School Fees'!$A$22:$C$31,2,FALSE),VLOOKUP('① Assumptions'!$B$14,'⑤ School Fees'!$A$22:$C$31,3,FALSE)))*(1-'① Assumptions'!$B$37)*(1+'① Assumptions'!$B$8)^E$3))) -> 0 | F14: =IF(OR(F$4<5,F$4>17),0,IF('① Assumptions'!$B$11="Public",IF(F$4<=11,'⑤ School Fees'!$B$18,'⑤ School Fees'!$C$18)*(1+'① Assumptions'!$B$8)^F$3,IF(F$4<IF('① Assumptions'!$B$12="Prep",5,IF('① Assumptions'!$B$12=5,10,IF('① Assumptions'!$B$12=7,12,IF('① Assumptions'!$B$12=9,14,17)))),IF(F$4<=11,'⑤ School Fees'!$B$18,'⑤ School Fees'!$C$18)*(1+'① Assumptions'!$B$8)^F$3,IF('① Assumptions'!$B$6="VIC",IF(F$4<=11,VLOOKUP('① Assumptions'!$B$13,'⑤ School Fees'!$A$6:$C$15,2,FALSE),VLOOKUP('① Assumptions'!$B$13,'⑤ School Fees'!$A$6:$C$15,3,FALSE)),IF(F$4<=11,VLOOKUP('① Assumptions'!$B$14,'⑤ School Fees'!$A$22:$C$31,2,FALSE),VLOOKUP('① Assumptions'!$B$14,'⑤ School Fees'!$A$22:$C$31,3,FALSE)))*(1-'① Assumptions'!$B$37)*(1+'① Assumptions'!$B$8)^F$3))) -> 0 | G14: =IF(OR(G$4<5,G$4>17),0,IF('① Assumptions'!$B$11="Public",IF(G$4<=11,'⑤ School Fees'!$B$18,'⑤ School Fees'!$C$18)*(1+'① Assumptions'!$B$8)^G$3,IF(G$4<IF('① Assumptions'!$B$12="Prep",5,IF('① Assumptions'!$B$12=5,10,IF('① Assumptions'!$B$12=7,12,IF('① Assumptions'!$B$12=9,14,17)))),IF(G$4<=11,'⑤ School Fees'!$B$18,'⑤ School Fees'!$C$18)*(1+'① Assumptions'!$B$8)^G$3,IF('① Assumptions'!$B$6="VIC",IF(G$4<=11,VLOOKUP('① Assumptions'!$B$13,'⑤ School Fees'!$A$6:$C$15,2,FALSE),VLOOKUP('① Assumptions'!$B$13,'⑤ School Fees'!$A$6:$C$15,3,FALSE)),IF(G$4<=11,VLOOKUP('① Assumptions'!$B$14,'⑤ School Fees'!$A$22:$C$31,2,FALSE),VLOOKUP('① Assumptions'!$B$14,'⑤ School Fees'!$A$22:$C$31,3,FALSE)))*(1-'① Assumptions'!$B$37)*(1+'① Assumptions'!$B$8)^G$3))) -> 0 | H14: =IF(OR(H$4<5,H$4>17),0,IF('① Assumptions'!$B$11="Public",IF(H$4<=11,'⑤ School Fees'!$B$18,'⑤ School Fees'!$C$18)*(1+'① Assumptions'!$B$8)^H$3,IF(H$4<IF('① Assumptions'!$B$12="Prep",5,IF('① Assumptions'!$B$12=5,10,IF('① Assumptions'!$B$12=7,12,IF('① Assumptions'!$B$12=9,14,17)))),IF(H$4<=11,'⑤ School Fees'!$B$18,'⑤ School Fees'!$C$18)*(1+'① Assumptions'!$B$8)^H$3,IF('① Assumptions'!$B$6="VIC",IF(H$4<=11,VLOOKUP('① Assumptions'!$B$13,'⑤ School Fees'!$A$6:$C$15,2,FALSE),VLOOKUP('① Assumptions'!$B$13,'⑤ School Fees'!$A$6:$C$15,3,FALSE)),IF(H$4<=11,VLOOKUP('① Assumptions'!$B$14,'⑤ School Fees'!$A$22:$C$31,2,FALSE),VLOOKUP('① Assumptions'!$B$14,'⑤ School Fees'!$A$22:$C$31,3,FALSE)))*(1-'① Assumptions'!$B$37)*(1+'① Assumptions'!$B$8)^H$3))) -> 0 | I14: =IF(OR(I$4<5,I$4>17),0,IF('① Assumptions'!$B$11="Public",IF(I$4<=11,'⑤ School Fees'!$B$18,'⑤ School Fees'!$C$18)*(1+'① Assumptions'!$B$8)^I$3,IF(I$4<IF('① Assumptions'!$B$12="Prep",5,IF('① Assumptions'!$B$12=5,10,IF('① Assumptions'!$B$12=7,12,IF('① Assumptions'!$B$12=9,14,17)))),IF(I$4<=11,'⑤ School Fees'!$B$18,'⑤ School Fees'!$C$18)*(1+'① Assumptions'!$B$8)^I$3,IF('① Assumptions'!$B$6="VIC",IF(I$4<=11,VLOOKUP('① Assumptions'!$B$13,'⑤ School Fees'!$A$6:$C$15,2,FALSE),VLOOKUP('① Assumptions'!$B$13,'⑤ School Fees'!$A$6:$C$15,3,FALSE)),IF(I$4<=11,VLOOKUP('① Assumptions'!$B$14,'⑤ School Fees'!$A$22:$C$31,2,FALSE),VLOOKUP('① Assumptions'!$B$14,'⑤ School Fees'!$A$22:$C$31,3,FALSE)))*(1-'① Assumptions'!$B$37)*(1+'① Assumptions'!$B$8)^I$3))) -> 638.14078 | J14: =IF(OR(J$4<5,J$4>17),0,IF('① Assumptions'!$B$11="Public",IF(J$4<=11,'⑤ School Fees'!$B$18,'⑤ School Fees'!$C$18)*(1+'① Assumptions'!$B$8)^J$3,IF(J$4<IF('① Assumptions'!$B$12="Prep",5,IF('① Assumptions'!$B$12=5,10,IF('① Assumptions'!$B$12=7,12,IF('① Assumptions'!$B$12=9,14,17)))),IF(J$4<=11,'⑤ School Fees'!$B$18,'⑤ School Fees'!$C$18)*(1+'① Assumptions'!$B$8)^J$3,IF('① Assumptions'!$B$6="VIC",IF(J$4<=11,VLOOKUP('① Assumptions'!$B$13,'⑤ School Fees'!$A$6:$C$15,2,FALSE),VLOOKUP('① Assumptions'!$B$13,'⑤ School Fees'!$A$6:$C$15,3,FALSE)),IF(J$4<=11,VLOOKUP('① Assumptions'!$B$14,'⑤ School Fees'!$A$22:$C$31,2,FALSE),VLOOKUP('① Assumptions'!$B$14,'⑤ School Fees'!$A$22:$C$31,3,FALSE)))*(1-'① Assumptions'!$B$37)*(1+'① Assumptions'!$B$8)^J$3))) -> 670.04782 | K14: =IF(OR(K$4<5,K$4>17),0,IF('① Assumptions'!$B$11="Public",IF(K$4<=11,'⑤ School Fees'!$B$18,'⑤ School Fees'!$C$18)*(1+'① Assumptions'!$B$8)^K$3,IF(K$4<IF('① Assumptions'!$B$12="Prep",5,IF('① Assumptions'!$B$12=5,10,IF('① Assumptions'!$B$12=7,12,IF('① Assumptions'!$B$12=9,14,17)))),IF(K$4<=11,'⑤ School Fees'!$B$18,'⑤ School Fees'!$C$18)*(1+'① Assumptions'!$B$8)^K$3,IF('① Assumptions'!$B$6="VIC",IF(K$4<=11,VLOOKUP('① Assumptions'!$B$13,'⑤ School Fees'!$A$6:$C$15,2,FALSE),VLOOKUP('① Assumptions'!$B$13,'⑤ School Fees'!$A$6:$C$15,3,FALSE)),IF(K$4<=11,VLOOKUP('① Assumptions'!$B$14,'⑤ School Fees'!$A$22:$C$31,2,FALSE),VLOOKUP('① Assumptions'!$B$14,'⑤ School Fees'!$A$22:$C$31,3,FALSE)))*(1-'① Assumptions'!$B$37)*(1+'① Assumptions'!$B$8)^K$3))) -> 703.55021 | ... Y14: =IF(OR(Y$4<5,Y$4>17),0,IF('① Assumptions'!$B$11="Public",IF(Y$4<=11,'⑤ School Fees'!$B$18,'⑤ School Fees'!$C$18)*(1+'① Assumptions'!$B$8)^Y$3,IF(Y$4<IF('① Assumptions'!$B$12="Prep",5,IF('① Assumptions'!$B$12=5,10,IF('① Assumptions'!$B$12=7,12,IF('① Assumptions'!$B$12=9,14,17)))),IF(Y$4<=11,'⑤ School Fees'!$B$18,'⑤ School Fees'!$C$18)*(1+'① Assumptions'!$B$8)^Y$3,IF('① Assumptions'!$B$6="VIC",IF(Y$4<=11,VLOOKUP('① Assumptions'!$B$13,'⑤ School Fees'!$A$6:$C$15,2,FALSE),VLOOKUP('① Assumptions'!$B$13,'⑤ School Fees'!$A$6:$C$15,3,FALSE)),IF(Y$4<=11,VLOOKUP('① Assumptions'!$B$14,'⑤ School Fees'!$A$22:$C$31,2,FALSE),VLOOKUP('① Assumptions'!$B$14,'⑤ School Fees'!$A$22:$C$31,3,FALSE)))*(1-'① Assumptions'!$B$37)*(1+'① Assumptions'!$B$8)^Y$3))) -> 0 | Z14: =SUM(D14:Y14) -> 14967.954
A15: 👕 Uniforms | B15: Costs | C15: Uniforms | D15: =IF(AND(D$4>=5,D$4<=17),'① Assumptions'!$B$85*(1+'① Assumptions'!$B$7)^D$3,0) -> 0 | E15: =IF(AND(E$4>=5,E$4<=17),'① Assumptions'!$B$85*(1+'① Assumptions'!$B$7)^E$3,0) -> 0 | F15: =IF(AND(F$4>=5,F$4<=17),'① Assumptions'!$B$85*(1+'① Assumptions'!$B$7)^F$3,0) -> 0 | G15: =IF(AND(G$4>=5,G$4<=17),'① Assumptions'!$B$85*(1+'① Assumptions'!$B$7)^G$3,0) -> 0 | H15: =IF(AND(H$4>=5,H$4<=17),'① Assumptions'!$B$85*(1+'① Assumptions'!$B$7)^H$3,0) -> 0 | I15: =IF(AND(I$4>=5,I$4<=17),'① Assumptions'!$B$85*(1+'① Assumptions'!$B$7)^I$3,0) -> 1738.9111 | J15: =IF(AND(J$4>=5,J$4<=17),'① Assumptions'!$B$85*(1+'① Assumptions'!$B$7)^J$3,0) -> 1791.0784 | K15: =IF(AND(K$4>=5,K$4<=17),'① Assumptions'!$B$85*(1+'① Assumptions'!$B$7)^K$3,0) -> 1844.8108 | ... Y15: =IF(AND(Y$4>=5,Y$4<=17),'① Assumptions'!$B$85*(1+'① Assumptions'!$B$7)^Y$3,0) -> 0 | Z15: =SUM(D15:Y15) -> 27157.949
A16: ⛺ Camps & Excursions | B16: Costs | C16: Camps & Excursions | D16: =IF(AND(D$4>=5,D$4<=17),'① Assumptions'!$B$86*(1+'① Assumptions'!$B$7)^D$3,0) -> 0 | E16: =IF(AND(E$4>=5,E$4<=17),'① Assumptions'!$B$86*(1+'① Assumptions'!$B$7)^E$3,0) -> 0 | F16: =IF(AND(F$4>=5,F$4<=17),'① Assumptions'!$B$86*(1+'① Assumptions'!$B$7)^F$3,0) -> 0 | G16: =IF(AND(G$4>=5,G$4<=17),'① Assumptions'!$B$86*(1+'① Assumptions'!$B$7)^G$3,0) -> 0 | H16: =IF(AND(H$4>=5,H$4<=17),'① Assumptions'!$B$86*(1+'① Assumptions'!$B$7)^H$3,0) -> 0 | I16: =IF(AND(I$4>=5,I$4<=17),'① Assumptions'!$B$86*(1+'① Assumptions'!$B$7)^I$3,0) -> 1159.2741 | J16: =IF(AND(J$4>=5,J$4<=17),'① Assumptions'!$B$86*(1+'① Assumptions'!$B$7)^J$3,0) -> 1194.0523 | K16: =IF(AND(K$4>=5,K$4<=17),'① Assumptions'!$B$86*(1+'① Assumptions'!$B$7)^K$3,0) -> 1229.8739 | ... Y16: =IF(AND(Y$4>=5,Y$4<=17),'① Assumptions'!$B$86*(1+'① Assumptions'!$B$7)^Y$3,0) -> 0 | Z16: =SUM(D16:Y16) -> 18105.3
A17: ⚽ Extra-Curriculars | B17: Costs | C17: Extra-Curriculars | D17: {=SUMPRODUCT(('① Assumptions'!$B$59:$B$64="Yes")*1,(D$4>='① Assumptions'!$D$59:$D$64)*1,(D$4<='① Assumptions'!$E$59:$E$64)*1,'① Assumptions'!$C$59:$C$64)*(1+'① Assumptions'!$B$7)^D$3} -> 0 | E17: {=SUMPRODUCT(('① Assumptions'!$B$59:$B$64="Yes")*1,(E$4>='① Assumptions'!$D$59:$D$64)*1,(E$4<='① Assumptions'!$E$59:$E$64)*1,'① Assumptions'!$C$59:$C$64)*(1+'① Assumptions'!$B$7)^E$3} -> 0 | F17: {=SUMPRODUCT(('① Assumptions'!$B$59:$B$64="Yes")*1,(F$4>='① Assumptions'!$D$59:$D$64)*1,(F$4<='① Assumptions'!$E$59:$E$64)*1,'① Assumptions'!$C$59:$C$64)*(1+'① Assumptions'!$B$7)^F$3} -> 0 | G17: {=SUMPRODUCT(('① Assumptions'!$B$59:$B$64="Yes")*1,(G$4>='① Assumptions'!$D$59:$D$64)*1,(G$4<='① Assumptions'!$E$59:$E$64)*1,'① Assumptions'!$C$59:$C$64)*(1+'① Assumptions'!$B$7)^G$3} -> 1311.2724 | H17: {=SUMPRODUCT(('① Assumptions'!$B$59:$B$64="Yes")*1,(H$4>='① Assumptions'!$D$59:$D$64)*1,(H$4<='① Assumptions'!$E$59:$E$64)*1,'① Assumptions'!$C$59:$C$64)*(1+'① Assumptions'!$B$7)^H$3} -> 1350.6106 | I17: {=SUMPRODUCT(('① Assumptions'!$B$59:$B$64="Yes")*1,(I$4>='① Assumptions'!$D$59:$D$64)*1,(I$4<='① Assumptions'!$E$59:$E$64)*1,'① Assumptions'!$C$59:$C$64)*(1+'① Assumptions'!$B$7)^I$3} -> 6607.8622 | J17: {=SUMPRODUCT(('① Assumptions'!$B$59:$B$64="Yes")*1,(J$4>='① Assumptions'!$D$59:$D$64)*1,(J$4<='① Assumptions'!$E$59:$E$64)*1,'① Assumptions'!$C$59:$C$64)*(1+'① Assumptions'!$B$7)^J$3} -> 10388.255 | K17: {=SUMPRODUCT(('① Assumptions'!$B$59:$B$64="Yes")*1,(K$4>='① Assumptions'!$D$59:$D$64)*1,(K$4<='① Assumptions'!$E$59:$E$64)*1,'① Assumptions'!$C$59:$C$64)*(1+'① Assumptions'!$B$7)^K$3} -> 10699.903 | ... Y17: {=SUMPRODUCT(('① Assumptions'!$B$59:$B$64="Yes")*1,(Y$4>='① Assumptions'!$D$59:$D$64)*1,(Y$4<='① Assumptions'!$E$59:$E$64)*1,'① Assumptions'!$C$59:$C$64)*(1+'① Assumptions'!$B$7)^Y$3} -> 0 | Z17: =SUM(D17:Y17) -> 207947.54
A18: 💻 Technology | B18: Costs | C18: Technology | D18: =(IF(AND(D$4>='① Assumptions'!$B$69,D$4<=20,MOD(D$4-'① Assumptions'!$B$69,'① Assumptions'!$B$68)=0),'① Assumptions'!$B$67,0)+IF(AND(D$4>='① Assumptions'!$B$70,D$4<=20,MOD(D$4-'① Assumptions'!$B$70,'① Assumptions'!$B$72)=0),'① Assumptions'!$B$71,0))*(1+'① Assumptions'!$B$7)^D$3 -> 0 | E18: =(IF(AND(E$4>='① Assumptions'!$B$69,E$4<=20,MOD(E$4-'① Assumptions'!$B$69,'① Assumptions'!$B$68)=0),'① Assumptions'!$B$67,0)+IF(AND(E$4>='① Assumptions'!$B$70,E$4<=20,MOD(E$4-'① Assumptions'!$B$70,'① Assumptions'!$B$72)=0),'① Assumptions'!$B$71,0))*(1+'① Assumptions'!$B$7)^E$3 -> 0 | F18: =(IF(AND(F$4>='① Assumptions'!$B$69,F$4<=20,MOD(F$4-'① Assumptions'!$B$69,'① Assumptions'!$B$68)=0),'① Assumptions'!$B$67,0)+IF(AND(F$4>='① Assumptions'!$B$70,F$4<=20,MOD(F$4-'① Assumptions'!$B$70,'① Assumptions'!$B$72)=0),'① Assumptions'!$B$71,0))*(1+'① Assumptions'!$B$7)^F$3 -> 0 | G18: =(IF(AND(G$4>='① Assumptions'!$B$69,G$4<=20,MOD(G$4-'① Assumptions'!$B$69,'① Assumptions'!$B$68)=0),'① Assumptions'!$B$67,0)+IF(AND(G$4>='① Assumptions'!$B$70,G$4<=20,MOD(G$4-'① Assumptions'!$B$70,'① Assumptions'!$B$72)=0),'① Assumptions'!$B$71,0))*(1+'① Assumptions'!$B$7)^G$3 -> 0 | H18: =(IF(AND(H$4>='① Assumptions'!$B$69,H$4<=20,MOD(H$4-'① Assumptions'!$B$69,'① Assumptions'!$B$68)=0),'① Assumptions'!$B$67,0)+IF(AND(H$4>='① Assumptions'!$B$70,H$4<=20,MOD(H$4-'① Assumptions'!$B$70,'① Assumptions'!$B$72)=0),'① Assumptions'!$B$71,0))*(1+'① Assumptions'!$B$7)^H$3 -> 0 | I18: =(IF(AND(I$4>='① Assumptions'!$B$69,I$4<=20,MOD(I$4-'① Assumptions'!$B$69,'① Assumptions'!$B$68)=0),'① Assumptions'!$B$67,0)+IF(AND(I$4>='① Assumptions'!$B$70,I$4<=20,MOD(I$4-'① Assumptions'!$B$70,'① Assumptions'!$B$72)=0),'① Assumptions'!$B$71,0))*(1+'① Assumptions'!$B$7)^I$3 -> 0 | J18: =(IF(AND(J$4>='① Assumptions'!$B$69,J$4<=20,MOD(J$4-'① Assumptions'!$B$69,'① Assumptions'!$B$68)=0),'① Assumptions'!$B$67,0)+IF(AND(J$4>='① Assumptions'!$B$70,J$4<=20,MOD(J$4-'① Assumptions'!$B$70,'① Assumptions'!$B$72)=0),'① Assumptions'!$B$71,0))*(1+'① Assumptions'!$B$7)^J$3 -> 0 | K18: =(IF(AND(K$4>='① Assumptions'!$B$69,K$4<=20,MOD(K$4-'① Assumptions'!$B$69,'① Assumptions'!$B$68)=0),'① Assumptions'!$B$67,0)+IF(AND(K$4>='① Assumptions'!$B$70,K$4<=20,MOD(K$4-'① Assumptions'!$B$70,'① Assumptions'!$B$72)=0),'① Assumptions'!$B$71,0))*(1+'① Assumptions'!$B$7)^K$3 -> 0 | ... Y18: =(IF(AND(Y$4>='① Assumptions'!$B$69,Y$4<=20,MOD(Y$4-'① Assumptions'!$B$69,'① Assumptions'!$B$68)=0),'① Assumptions'!$B$67,0)+IF(AND(Y$4>='① Assumptions'!$B$70,Y$4<=20,MOD(Y$4-'① Assumptions'!$B$70,'① Assumptions'!$B$72)=0),'① Assumptions'!$B$71,0))*(1+'① Assumptions'!$B$7)^Y$3 -> 0 | Z18: =SUM(D18:Y18) -> 17964.719
A19: 🏥 Health Insurance | B19: Costs | C19: Health Insurance | D19: ='① Assumptions'!$B$47*(1+'① Assumptions'!$B$48)^D$3 -> 4500 | E19: ='① Assumptions'!$B$47*(1+'① Assumptions'!$B$48)^E$3 -> 4770 | F19: ='① Assumptions'!$B$47*(1+'① Assumptions'!$B$48)^F$3 -> 5056.2 | G19: ='① Assumptions'!$B$47*(1+'① Assumptions'!$B$48)^G$3 -> 5359.572 | H19: ='① Assumptions'!$B$47*(1+'① Assumptions'!$B$48)^H$3 -> 5681.1463 | I19: ='① Assumptions'!$B$47*(1+'① Assumptions'!$B$48)^I$3 -> 6022.0151 | J19: ='① Assumptions'!$B$47*(1+'① Assumptions'!$B$48)^J$3 -> 6383.336 | K19: ='① Assumptions'!$B$47*(1+'① Assumptions'!$B$48)^K$3 -> 6766.3362 | ... Y19: ='① Assumptions'!$B$47*(1+'① Assumptions'!$B$48)^Y$3 -> 15298.036 | Z19: =SUM(D19:Y19) -> 195265.31
A20: 🦷 Orthodontics | B20: Costs | C20: Orthodontics | D20: =IF(AND(D$4>='① Assumptions'!$B$51,D$4<'① Assumptions'!$B$51+'① Assumptions'!$B$52),('① Assumptions'!$B$50/'① Assumptions'!$B$52)*(1+'① Assumptions'!$B$7)^D$3,0) -> 0 | E20: =IF(AND(E$4>='① Assumptions'!$B$51,E$4<'① Assumptions'!$B$51+'① Assumptions'!$B$52),('① Assumptions'!$B$50/'① Assumptions'!$B$52)*(1+'① Assumptions'!$B$7)^E$3,0) -> 0 | F20: =IF(AND(F$4>='① Assumptions'!$B$51,F$4<'① Assumptions'!$B$51+'① Assumptions'!$B$52),('① Assumptions'!$B$50/'① Assumptions'!$B$52)*(1+'① Assumptions'!$B$7)^F$3,0) -> 0 | G20: =IF(AND(G$4>='① Assumptions'!$B$51,G$4<'① Assumptions'!$B$51+'① Assumptions'!$B$52),('① Assumptions'!$B$50/'① Assumptions'!$B$52)*(1+'① Assumptions'!$B$7)^G$3,0) -> 0 | H20: =IF(AND(H$4>='① Assumptions'!$B$51,H$4<'① Assumptions'!$B$51+'① Assumptions'!$B$52),('① Assumptions'!$B$50/'① Assumptions'!$B$52)*(1+'① Assumptions'!$B$7)^H$3,0) -> 0 | I20: =IF(AND(I$4>='① Assumptions'!$B$51,I$4<'① Assumptions'!$B$51+'① Assumptions'!$B$52),('① Assumptions'!$B$50/'① Assumptions'!$B$52)*(1+'① Assumptions'!$B$7)^I$3,0) -> 0 | J20: =IF(AND(J$4>='① Assumptions'!$B$51,J$4<'① Assumptions'!$B$51+'① Assumptions'!$B$52),('① Assumptions'!$B$50/'① Assumptions'!$B$52)*(1+'① Assumptions'!$B$7)^J$3,0) -> 0 | K20: =IF(AND(K$4>='① Assumptions'!$B$51,K$4<'① Assumptions'!$B$51+'① Assumptions'!$B$52),('① Assumptions'!$B$50/'① Assumptions'!$B$52)*(1+'① Assumptions'!$B$7)^K$3,0) -> 0 | ... Y20: =IF(AND(Y$4>='① Assumptions'!$B$51,Y$4<'① Assumptions'!$B$51+'① Assumptions'!$B$52),('① Assumptions'!$B$50/'① Assumptions'!$B$52)*(1+'① Assumptions'!$B$7)^Y$3,0) -> 0 | Z20: =SUM(D20:Y20) -> 10130.031
A21: ⚕️ Allied Health | B21: Costs | C21: Allied Health | D21: =IF(AND(D$4>=VALUE(LEFT('① Assumptions'!$B$54,FIND("–",'① Assumptions'!$B$54)-1)),D$4<=VALUE(MID('① Assumptions'!$B$54,FIND("–",'① Assumptions'!$B$54)+1,10))),'① Assumptions'!$B$53*(1+'① Assumptions'!$B$7)^D$3,0) -> 0 | E21: =IF(AND(E$4>=VALUE(LEFT('① Assumptions'!$B$54,FIND("–",'① Assumptions'!$B$54)-1)),E$4<=VALUE(MID('① Assumptions'!$B$54,FIND("–",'① Assumptions'!$B$54)+1,10))),'① Assumptions'!$B$53*(1+'① Assumptions'!$B$7)^E$3,0) -> 0 | F21: =IF(AND(F$4>=VALUE(LEFT('① Assumptions'!$B$54,FIND("–",'① Assumptions'!$B$54)-1)),F$4<=VALUE(MID('① Assumptions'!$B$54,FIND("–",'① Assumptions'!$B$54)+1,10))),'① Assumptions'!$B$53*(1+'① Assumptions'!$B$7)^F$3,0) -> 0 | G21: =IF(AND(G$4>=VALUE(LEFT('① Assumptions'!$B$54,FIND("–",'① Assumptions'!$B$54)-1)),G$4<=VALUE(MID('① Assumptions'!$B$54,FIND("–",'① Assumptions'!$B$54)+1,10))),'① Assumptions'!$B$53*(1+'① Assumptions'!$B$7)^G$3,0) -> 2185.454 | H21: =IF(AND(H$4>=VALUE(LEFT('① Assumptions'!$B$54,FIND("–",'① Assumptions'!$B$54)-1)),H$4<=VALUE(MID('① Assumptions'!$B$54,FIND("–",'① Assumptions'!$B$54)+1,10))),'① Assumptions'!$B$53*(1+'① Assumptions'!$B$7)^H$3,0) -> 2251.0176 | I21: =IF(AND(I$4>=VALUE(LEFT('① Assumptions'!$B$54,FIND("–",'① Assumptions'!$B$54)-1)),I$4<=VALUE(MID('① Assumptions'!$B$54,FIND("–",'① Assumptions'!$B$54)+1,10))),'① Assumptions'!$B$53*(1+'① Assumptions'!$B$7)^I$3,0) -> 2318.5481 | J21: =IF(AND(J$4>=VALUE(LEFT('① Assumptions'!$B$54,FIND("–",'① Assumptions'!$B$54)-1)),J$4<=VALUE(MID('① Assumptions'!$B$54,FIND("–",'① Assumptions'!$B$54)+1,10))),'① Assumptions'!$B$53*(1+'① Assumptions'!$B$7)^J$3,0) -> 2388.1046 | K21: =IF(AND(K$4>=VALUE(LEFT('① Assumptions'!$B$54,FIND("–",'① Assumptions'!$B$54)-1)),K$4<=VALUE(MID('① Assumptions'!$B$54,FIND("–",'① Assumptions'!$B$54)+1,10))),'① Assumptions'!$B$53*(1+'① Assumptions'!$B$7)^K$3,0) -> 2459.7477 | ... Y21: =IF(AND(Y$4>=VALUE(LEFT('① Assumptions'!$B$54,FIND("–",'① Assumptions'!$B$54)-1)),Y$4<=VALUE(MID('① Assumptions'!$B$54,FIND("–",'① Assumptions'!$B$54)+1,10))),'① Assumptions'!$B$53*(1+'① Assumptions'!$B$7)^Y$3,0) -> 0 | Z21: =SUM(D21:Y21) -> 14136.412
A22: 🚗 Driving Lessons | B22: Costs | C22: Driving | D22: =IF(AND('① Assumptions'!$B$75="Yes",D$4='① Assumptions'!$B$77),'① Assumptions'!$B$76*(1+'① Assumptions'!$B$7)^D$3,0) -> 0 | E22: =IF(AND('① Assumptions'!$B$75="Yes",E$4='① Assumptions'!$B$77),'① Assumptions'!$B$76*(1+'① Assumptions'!$B$7)^E$3,0) -> 0 | F22: =IF(AND('① Assumptions'!$B$75="Yes",F$4='① Assumptions'!$B$77),'① Assumptions'!$B$76*(1+'① Assumptions'!$B$7)^F$3,0) -> 0 | G22: =IF(AND('① Assumptions'!$B$75="Yes",G$4='① Assumptions'!$B$77),'① Assumptions'!$B$76*(1+'① Assumptions'!$B$7)^G$3,0) -> 0 | H22: =IF(AND('① Assumptions'!$B$75="Yes",H$4='① Assumptions'!$B$77),'① Assumptions'!$B$76*(1+'① Assumptions'!$B$7)^H$3,0) -> 0 | I22: =IF(AND('① Assumptions'!$B$75="Yes",I$4='① Assumptions'!$B$77),'① Assumptions'!$B$76*(1+'① Assumptions'!$B$7)^I$3,0) -> 0 | J22: =IF(AND('① Assumptions'!$B$75="Yes",J$4='① Assumptions'!$B$77),'① Assumptions'!$B$76*(1+'① Assumptions'!$B$7)^J$3,0) -> 0 | K22: =IF(AND('① Assumptions'!$B$75="Yes",K$4='① Assumptions'!$B$77),'① Assumptions'!$B$76*(1+'① Assumptions'!$B$7)^K$3,0) -> 0 | ... Y22: =IF(AND('① Assumptions'!$B$75="Yes",Y$4='① Assumptions'!$B$77),'① Assumptions'!$B$76*(1+'① Assumptions'!$B$7)^Y$3,0) -> 0 | Z22: =SUM(D22:Y22) -> 2407.0597
A23: 🚙 Car Costs | B23: Costs | C23: Car Costs | D23: =IF('① Assumptions'!$B$75="Yes",IF(D$4='① Assumptions'!$B$79,'① Assumptions'!$B$78*(1+'① Assumptions'!$B$7)^D$3,0)+IF(AND(D$4>='① Assumptions'!$B$79,D$4<=21),'① Assumptions'!$B$80*(1+'① Assumptions'!$B$7)^D$3,0),0) -> 0 | E23: =IF('① Assumptions'!$B$75="Yes",IF(E$4='① Assumptions'!$B$79,'① Assumptions'!$B$78*(1+'① Assumptions'!$B$7)^E$3,0)+IF(AND(E$4>='① Assumptions'!$B$79,E$4<=21),'① Assumptions'!$B$80*(1+'① Assumptions'!$B$7)^E$3,0),0) -> 0 | F23: =IF('① Assumptions'!$B$75="Yes",IF(F$4='① Assumptions'!$B$79,'① Assumptions'!$B$78*(1+'① Assumptions'!$B$7)^F$3,0)+IF(AND(F$4>='① Assumptions'!$B$79,F$4<=21),'① Assumptions'!$B$80*(1+'① Assumptions'!$B$7)^F$3,0),0) -> 0 | G23: =IF('① Assumptions'!$B$75="Yes",IF(G$4='① Assumptions'!$B$79,'① Assumptions'!$B$78*(1+'① Assumptions'!$B$7)^G$3,0)+IF(AND(G$4>='① Assumptions'!$B$79,G$4<=21),'① Assumptions'!$B$80*(1+'① Assumptions'!$B$7)^G$3,0),0) -> 0 | H23: =IF('① Assumptions'!$B$75="Yes",IF(H$4='① Assumptions'!$B$79,'① Assumptions'!$B$78*(1+'① Assumptions'!$B$7)^H$3,0)+IF(AND(H$4>='① Assumptions'!$B$79,H$4<=21),'① Assumptions'!$B$80*(1+'① Assumptions'!$B$7)^H$3,0),0) -> 0 | I23: =IF('① Assumptions'!$B$75="Yes",IF(I$4='① Assumptions'!$B$79,'① Assumptions'!$B$78*(1+'① Assumptions'!$B$7)^I$3,0)+IF(AND(I$4>='① Assumptions'!$B$79,I$4<=21),'① Assumptions'!$B$80*(1+'① Assumptions'!$B$7)^I$3,0),0) -> 0 | J23: =IF('① Assumptions'!$B$75="Yes",IF(J$4='① Assumptions'!$B$79,'① Assumptions'!$B$78*(1+'① Assumptions'!$B$7)^J$3,0)+IF(AND(J$4>='① Assumptions'!$B$79,J$4<=21),'① Assumptions'!$B$80*(1+'① Assumptions'!$B$7)^J$3,0),0) -> 0 | K23: =IF('① Assumptions'!$B$75="Yes",IF(K$4='① Assumptions'!$B$79,'① Assumptions'!$B$78*(1+'① Assumptions'!$B$7)^K$3,0)+IF(AND(K$4>='① Assumptions'!$B$79,K$4<=21),'① Assumptions'!$B$80*(1+'① Assumptions'!$B$7)^K$3,0),0) -> 0 | ... Y23: =IF('① Assumptions'!$B$75="Yes",IF(Y$4='① Assumptions'!$B$79,'① Assumptions'!$B$78*(1+'① Assumptions'!$B$7)^Y$3,0)+IF(AND(Y$4>='① Assumptions'!$B$79,Y$4<=21),'① Assumptions'!$B$80*(1+'① Assumptions'!$B$7)^Y$3,0),0) -> 5580.8837 | Z23: =SUM(D23:Y23) -> 46903.531
A24: 🌍 Gap Year | B24: Costs | C24: Gap Year | D24: =IF(AND('① Assumptions'!$B$83="Yes",D$4=18),'① Assumptions'!$B$84*(1+'① Assumptions'!$B$7)^D$3,0) -> 0 | E24: =IF(AND('① Assumptions'!$B$83="Yes",E$4=18),'① Assumptions'!$B$84*(1+'① Assumptions'!$B$7)^E$3,0) -> 0 | F24: =IF(AND('① Assumptions'!$B$83="Yes",F$4=18),'① Assumptions'!$B$84*(1+'① Assumptions'!$B$7)^F$3,0) -> 0 | G24: =IF(AND('① Assumptions'!$B$83="Yes",G$4=18),'① Assumptions'!$B$84*(1+'① Assumptions'!$B$7)^G$3,0) -> 0 | H24: =IF(AND('① Assumptions'!$B$83="Yes",H$4=18),'① Assumptions'!$B$84*(1+'① Assumptions'!$B$7)^H$3,0) -> 0 | I24: =IF(AND('① Assumptions'!$B$83="Yes",I$4=18),'① Assumptions'!$B$84*(1+'① Assumptions'!$B$7)^I$3,0) -> 0 | J24: =IF(AND('① Assumptions'!$B$83="Yes",J$4=18),'① Assumptions'!$B$84*(1+'① Assumptions'!$B$7)^J$3,0) -> 0 | K24: =IF(AND('① Assumptions'!$B$83="Yes",K$4=18),'① Assumptions'!$B$84*(1+'① Assumptions'!$B$7)^K$3,0) -> 0 | ... Y24: =IF(AND('① Assumptions'!$B$83="Yes",Y$4=18),'① Assumptions'!$B$84*(1+'① Assumptions'!$B$7)^Y$3,0) -> 0 | Z24: =SUM(D24:Y24) -> 0
A25: 🎓 University Fees | B25: Costs | C25: University Fees | D25: =IF('① Assumptions'!$B$83="Yes",IF(AND(D$4>=19,D$4<=18+'① Assumptions'!$B$36),(IF('① Assumptions'!$B$39="Domestic",IF('① Assumptions'!$B$40="Band 1",'⑥ University'!$B$6,IF('① Assumptions'!$B$40="Band 2",'⑥ University'!$B$7,IF('① Assumptions'!$B$40="Band 3",'⑥ University'!$B$8,'⑥ University'!$B$9))),'① Assumptions'!$B$41)*(1-'① Assumptions'!$B$38))*(1+'① Assumptions'!$B$8)^D$3,0),IF(AND(D$4>=18,D$4<=17+'① Assumptions'!$B$36),(IF('① Assumptions'!$B$39="Domestic",IF('① Assumptions'!$B$40="Band 1",'⑥ University'!$B$6,IF('① Assumptions'!$B$40="Band 2",'⑥ University'!$B$7,IF('① Assumptions'!$B$40="Band 3",'⑥ University'!$B$8,'⑥ University'!$B$9))),'① Assumptions'!$B$41)*(1-'① Assumptions'!$B$38))*(1+'① Assumptions'!$B$8)^D$3,0)) -> 0 | E25: =IF('① Assumptions'!$B$83="Yes",IF(AND(E$4>=19,E$4<=18+'① Assumptions'!$B$36),(IF('① Assumptions'!$B$39="Domestic",IF('① Assumptions'!$B$40="Band 1",'⑥ University'!$B$6,IF('① Assumptions'!$B$40="Band 2",'⑥ University'!$B$7,IF('① Assumptions'!$B$40="Band 3",'⑥ University'!$B$8,'⑥ University'!$B$9))),'① Assumptions'!$B$41)*(1-'① Assumptions'!$B$38))*(1+'① Assumptions'!$B$8)^E$3,0),IF(AND(E$4>=18,E$4<=17+'① Assumptions'!$B$36),(IF('① Assumptions'!$B$39="Domestic",IF('① Assumptions'!$B$40="Band 1",'⑥ University'!$B$6,IF('① Assumptions'!$B$40="Band 2",'⑥ University'!$B$7,IF('① Assumptions'!$B$40="Band 3",'⑥ University'!$B$8,'⑥ University'!$B$9))),'① Assumptions'!$B$41)*(1-'① Assumptions'!$B$38))*(1+'① Assumptions'!$B$8)^E$3,0)) -> 0 | F25: =IF('① Assumptions'!$B$83="Yes",IF(AND(F$4>=19,F$4<=18+'① Assumptions'!$B$36),(IF('① Assumptions'!$B$39="Domestic",IF('① Assumptions'!$B$40="Band 1",'⑥ University'!$B$6,IF('① Assumptions'!$B$40="Band 2",'⑥ University'!$B$7,IF('① Assumptions'!$B$40="Band 3",'⑥ University'!$B$8,'⑥ University'!$B$9))),'① Assumptions'!$B$41)*(1-'① Assumptions'!$B$38))*(1+'① Assumptions'!$B$8)^F$3,0),IF(AND(F$4>=18,F$4<=17+'① Assumptions'!$B$36),(IF('① Assumptions'!$B$39="Domestic",IF('① Assumptions'!$B$40="Band 1",'⑥ University'!$B$6,IF('① Assumptions'!$B$40="Band 2",'⑥ University'!$B$7,IF('① Assumptions'!$B$40="Band 3",'⑥ University'!$B$8,'⑥ University'!$B$9))),'① Assumptions'!$B$41)*(1-'① Assumptions'!$B$38))*(1+'① Assumptions'!$B$8)^F$3,0)) -> 0 | G25: =IF('① Assumptions'!$B$83="Yes",IF(AND(G$4>=19,G$4<=18+'① Assumptions'!$B$36),(IF('① Assumptions'!$B$39="Domestic",IF('① Assumptions'!$B$40="Band 1",'⑥ University'!$B$6,IF('① Assumptions'!$B$40="Band 2",'⑥ University'!$B$7,IF('① Assumptions'!$B$40="Band 3",'⑥ University'!$B$8,'⑥ University'!$B$9))),'① Assumptions'!$B$41)*(1-'① Assumptions'!$B$38))*(1+'① Assumptions'!$B$8)^G$3,0),IF(AND(G$4>=18,G$4<=17+'① Assumptions'!$B$36),(IF('① Assumptions'!$B$39="Domestic",IF('① Assumptions'!$B$40="Band 1",'⑥ University'!$B$6,IF('① Assumptions'!$B$40="Band 2",'⑥ University'!$B$7,IF('① Assumptions'!$B$40="Band 3",'⑥ University'!$B$8,'⑥ University'!$B$9))),'① Assumptions'!$B$41)*(1-'① Assumptions'!$B$38))*(1+'① Assumptions'!$B$8)^G$3,0)) -> 0 | H25: =IF('① Assumptions'!$B$83="Yes",IF(AND(H$4>=19,H$4<=18+'① Assumptions'!$B$36),(IF('① Assumptions'!$B$39="Domestic",IF('① Assumptions'!$B$40="Band 1",'⑥ University'!$B$6,IF('① Assumptions'!$B$40="Band 2",'⑥ University'!$B$7,IF('① Assumptions'!$B$40="Band 3",'⑥ University'!$B$8,'⑥ University'!$B$9))),'① Assumptions'!$B$41)*(1-'① Assumptions'!$B$38))*(1+'① Assumptions'!$B$8)^H$3,0),IF(AND(H$4>=18,H$4<=17+'① Assumptions'!$B$36),(IF('① Assumptions'!$B$39="Domestic",IF('① Assumptions'!$B$40="Band 1",'⑥ University'!$B$6,IF('① Assumptions'!$B$40="Band 2",'⑥ University'!$B$7,IF('① Assumptions'!$B$40="Band 3",'⑥ University'!$B$8,'⑥ University'!$B$9))),'① Assumptions'!$B$41)*(1-'① Assumptions'!$B$38))*(1+'① Assumptions'!$B$8)^H$3,0)) -> 0 | I25: =IF('① Assumptions'!$B$83="Yes",IF(AND(I$4>=19,I$4<=18+'① Assumptions'!$B$36),(IF('① Assumptions'!$B$39="Domestic",IF('① Assumptions'!$B$40="Band 1",'⑥ University'!$B$6,IF('① Assumptions'!$B$40="Band 2",'⑥ University'!$B$7,IF('① Assumptions'!$B$40="Band 3",'⑥ University'!$B$8,'⑥ University'!$B$9))),'① Assumptions'!$B$41)*(1-'① Assumptions'!$B$38))*(1+'① Assumptions'!$B$8)^I$3,0),IF(AND(I$4>=18,I$4<=17+'① Assumptions'!$B$36),(IF('① Assumptions'!$B$39="Domestic",IF('① Assumptions'!$B$40="Band 1",'⑥ University'!$B$6,IF('① Assumptions'!$B$40="Band 2",'⑥ University'!$B$7,IF('① Assumptions'!$B$40="Band 3",'⑥ University'!$B$8,'⑥ University'!$B$9))),'① Assumptions'!$B$41)*(1-'① Assumptions'!$B$38))*(1+'① Assumptions'!$B$8)^I$3,0)) -> 0 | J25: =IF('① Assumptions'!$B$83="Yes",IF(AND(J$4>=19,J$4<=18+'① Assumptions'!$B$36),(IF('① Assumptions'!$B$39="Domestic",IF('① Assumptions'!$B$40="Band 1",'⑥ University'!$B$6,IF('① Assumptions'!$B$40="Band 2",'⑥ University'!$B$7,IF('① Assumptions'!$B$40="Band 3",'⑥ University'!$B$8,'⑥ University'!$B$9))),'① Assumptions'!$B$41)*(1-'① Assumptions'!$B$38))*(1+'① Assumptions'!$B$8)^J$3,0),IF(AND(J$4>=18,J$4<=17+'① Assumptions'!$B$36),(IF('① Assumptions'!$B$39="Domestic",IF('① Assumptions'!$B$40="Band 1",'⑥ University'!$B$6,IF('① Assumptions'!$B$40="Band 2",'⑥ University'!$B$7,IF('① Assumptions'!$B$40="Band 3",'⑥ University'!$B$8,'⑥ University'!$B$9))),'① Assumptions'!$B$41)*(1-'① Assumptions'!$B$38))*(1+'① Assumptions'!$B$8)^J$3,0)) -> 0 | K25: =IF('① Assumptions'!$B$83="Yes",IF(AND(K$4>=19,K$4<=18+'① Assumptions'!$B$36),(IF('① Assumptions'!$B$39="Domestic",IF('① Assumptions'!$B$40="Band 1",'⑥ University'!$B$6,IF('① Assumptions'!$B$40="Band 2",'⑥ University'!$B$7,IF('① Assumptions'!$B$40="Band 3",'⑥ University'!$B$8,'⑥ University'!$B$9))),'① Assumptions'!$B$41)*(1-'① Assumptions'!$B$38))*(1+'① Assumptions'!$B$8)^K$3,0),IF(AND(K$4>=18,K$4<=17+'① Assumptions'!$B$36),(IF('① Assumptions'!$B$39="Domestic",IF('① Assumptions'!$B$40="Band 1",'⑥ University'!$B$6,IF('① Assumptions'!$B$40="Band 2",'⑥ University'!$B$7,IF('① Assumptions'!$B$40="Band 3",'⑥ University'!$B$8,'⑥ University'!$B$9))),'① Assumptions'!$B$41)*(1-'① Assumptions'!$B$38))*(1+'① Assumptions'!$B$8)^K$3,0)) -> 0 | ... Y25: =IF('① Assumptions'!$B$83="Yes",IF(AND(Y$4>=19,Y$4<=18+'① Assumptions'!$B$36),(IF('① Assumptions'!$B$39="Domestic",IF('① Assumptions'!$B$40="Band 1",'⑥ University'!$B$6,IF('① Assumptions'!$B$40="Band 2",'⑥ University'!$B$7,IF('① Assumptions'!$B$40="Band 3",'⑥ University'!$B$8,'⑥ University'!$B$9))),'① Assumptions'!$B$41)*(1-'① Assumptions'!$B$38))*(1+'① Assumptions'!$B$8)^Y$3,0),IF(AND(Y$4>=18,Y$4<=17+'① Assumptions'!$B$36),(IF('① Assumptions'!$B$39="Domestic",IF('① Assumptions'!$B$40="Band 1",'⑥ University'!$B$6,IF('① Assumptions'!$B$40="Band 2",'⑥ University'!$B$7,IF('① Assumptions'!$B$40="Band 3",'⑥ University'!$B$8,'⑥ University'!$B$9))),'① Assumptions'!$B$41)*(1-'① Assumptions'!$B$38))*(1+'① Assumptions'!$B$8)^Y$3,0)) -> 0 | Z25: =SUM(D25:Y25) -> 60854.261
